Workbook
Name Slicer_District: #N/A
Name Slicer_District1: #N/A

Sheet DASHBOARD
E1: WB DEALERS AGING STOCK TRACKER DASHBOARD

Sheet N24
E1: NORTH 24 PARGANAS | R1: Total | S1: 12
R2: Subject | S2: Liquidation of RCF high Aging Stock
E6: AMAL SALES CORPORATION | R6: =HYPERLINK("https://mail.google.com/mail/?view=cm&to="&R8&"&su=Liquidation%20of%20RCF%20high%20Aging%20Stock","SEND EMAIL") -> SEND EMAIL
F7: Previous | L7: Current | R7: to
F8: UREA | G8: S-15 | H8: 10-26-26 | I8: MOP | J8: DAP | K8: TOTAL | L8: UREA | M8: S-15 | N8: 10-26-26 | O8: MOP | P8: DAP | Q8: TOTAL | R8: amalsalescorpn@gmail.com
E9: 181-365 | F9: =SUMIFS('WH+RT PREVIOUS'!$M$2:$M$15000,'WH+RT PREVIOUS'!$B$2:$B$15000,"N.C.Urea(45kg)",'WH+RT PREVIOUS'!$S$2:$S$15000,"Amal Sales Corporation",'WH+RT PREVIOUS'!$N$2:$N$15000,">179",'WH+RT PREVIOUS'!$N$2:$N$15000,"<366") -> 0 | G9: =SUMIFS('WH+RT PREVIOUS'!$M$2:$M$15000,'WH+RT PREVIOUS'!$B$2:$B$15000,"15-15-15",'WH+RT PREVIOUS'!$S$2:$S$15000,"Amal Sales Corporation",'WH+RT PREVIOUS'!$N$2:$N$15000,">179",'WH+RT PREVIOUS'!$N$2:$N$15000,"<366") -> 5.35 | H9: =SUMIFS('WH+RT PREVIOUS'!$M$2:$M$15000,'WH+RT PREVIOUS'!$B$2:$B$15000,"Imp 10-26-26",'WH+RT PREVIOUS'!$S$2:$S$15000,"Amal Sales Corporation",'WH+RT PREVIOUS'!$N$2:$N$15000,">179",'WH+RT PREVIOUS'!$N$2:$N$15000,"<366") -> 0 | I9: =SUMIFS('WH+RT PREVIOUS'!$M$2:$M$15000,'WH+RT PREVIOUS'!$B$2:$B$15000,"MOP",'WH+RT PREVIOUS'!$S$2:$S$15000,"Amal Sales Corporation",'WH+RT PREVIOUS'!$N$2:$N$15000,">179",'WH+RT PREVIOUS'!$N$2:$N$15000,"<366") -> 0 | J9: =SUMIFS('WH+RT PREVIOUS'!$M$2:$M$15000,'WH+RT PREVIOUS'!$B$2:$B$15000,"Imp DAP",'WH+RT PREVIOUS'!$S$2:$S$15000,"Amal Sales Corporation",'WH+RT PREVIOUS'!$N$2:$N$15000,">179",'WH+RT PREVIOUS'!$N$2:$N$15000,"<366") -> 0 | K9: =F9+G9+H9+I9 -> 5.35 | L9: =SUMIFS('WH+RT CURRENT'!$M$2:$M$15000,'WH+RT CURRENT'!$B$2:$B$15000,"N.C.Urea(45kg)",'WH+RT CURRENT'!$S$2:$S$15000,"Amal Sales Corporation",'WH+RT CURRENT'!$N$2:$N$15000,">179",'WH+RT CURRENT'!$N$2:$N$15000,"<366") -> 0.18 | M9: =SUMIFS('WH+RT CURRENT'!$M$2:$M$15000,'WH+RT CURRENT'!$B$2:$B$15000,"15-15-15",'WH+RT CURRENT'!$S$2:$S$15000,"Amal Sales Corporation",'WH+RT CURRENT'!$N$2:$N$15000,">179",'WH+RT CURRENT'!$N$2:$N$15000,"<366") -> 5.3 | N9: =SUMIFS('WH+RT CURRENT'!$M$2:$M$15000,'WH+RT CURRENT'!$B$2:$B$15000,"Imp 10-26-26",'WH+RT CURRENT'!$S$2:$S$15000,"Amal Sales Corporation",'WH+RT CURRENT'!$N$2:$N$15000,">179",'WH+RT CURRENT'!$N$2:$N$15000,"<366") -> 0 | O9: =SUMIFS('WH+RT CURRENT'!$M$2:$M$15000,'WH+RT CURRENT'!$B$2:$B$15000,"MOP",'WH+RT CURRENT'!$S$2:$S$15000,"Amal Sales Corporation",'WH+RT CURRENT'!$N$2:$N$15000,">179",'WH+RT CURRENT'!$N$2:$N$15000,"<366") -> 0 | P9: =SUMIFS('WH+RT CURRENT'!$M$2:$M$15000,'WH+RT CURRENT'!$B$2:$B$15000,"Imp DAP",'WH+RT CURRENT'!$S$2:$S$15000,"Amal Sales Corporation",'WH+RT CURRENT'!$N$2:$N$15000,">179",'WH+RT CURRENT'!$N$2:$N$15000,"<366") -> 0 | Q9: =L9+M9+N9+O9 -> 5.48
E10: 366+ | F10: =SUMIFS('WH+RT PREVIOUS'!$M$2:$M$15000,'WH+RT PREVIOUS'!$B$2:$B$15000,"N.C.Urea(45kg)",'WH+RT PREVIOUS'!$S$2:$S$15000,"Amal Sales Corporation",'WH+RT PREVIOUS'!$N$2:$N$15000,">365") -> 0.155 | G10: =SUMIFS('WH+RT PREVIOUS'!$M$2:$M$15000,'WH+RT PREVIOUS'!$B$2:$B$15000,"15-15-15",'WH+RT PREVIOUS'!$S$2:$S$15000,"Amal Sales Corporation",'WH+RT PREVIOUS'!$N$2:$N$15000,">365") -> 0.746 | H10: =SUMIFS('WH+RT PREVIOUS'!$M$2:$M$15000,'WH+RT PREVIOUS'!$B$2:$B$15000,"Imp 10-26-26",'WH+RT PREVIOUS'!$S$2:$S$15000,"Amal Sales Corporation",'WH+RT PREVIOUS'!$N$2:$N$15000,">365") -> 0 | I10: =SUMIFS('WH+RT PREVIOUS'!$M$2:$M$15000,'WH+RT PREVIOUS'!$B$2:$B$15000,"MOP",'WH+RT PREVIOUS'!$S$2:$S$15000,"Amal Sales Corporation",'WH+RT PREVIOUS'!$N$2:$N$15000,">365") -> 0 | J10: =SUMIFS('WH+RT PREVIOUS'!$M$2:$M$15000,'WH+RT PREVIOUS'!$B$2:$B$15000,"Imp DAP",'WH+RT PREVIOUS'!$S$2:$S$15000,"Amal Sales Corporation",'WH+RT PREVIOUS'!$N$2:$N$15000,">365") -> 0 | K10: =F10+G10+H10+I10 -> 0.901 | L10: =SUMIFS('WH+RT CURRENT'!$M$2:$M$15000,'WH+RT CURRENT'!$B$2:$B$15000,"N.C.Urea(45kg)",'WH+RT CURRENT'!$S$2:$S$15000,"Amal Sales Corporation",'WH+RT CURRENT'!$N$2:$N$15000,">365") -> 0.155 | M10: =SUMIFS('WH+RT CURRENT'!$M$2:$M$15000,'WH+RT CURRENT'!$B$2:$B$15000,"15-15-15",'WH+RT CURRENT'!$S$2:$S$15000,"Amal Sales Corporation",'WH+RT CURRENT'!$N$2:$N$15000,">365") -> 0.746 | N10: =SUMIFS('WH+RT CURRENT'!$M$2:$M$15000,'WH+RT CURRENT'!$B$2:$B$15000,"Imp 10-26-26",'WH+RT CURRENT'!$S$2:$S$15000,"Amal Sales Corporation",'WH+RT CURRENT'!$N$2:$N$15000,">365") -> 0 | O10: =SUMIFS('WH+RT CURRENT'!$M$2:$M$15000,'WH+RT CURRENT'!$B$2:$B$15000,"MOP",'WH+RT CURRENT'!$S$2:$S$15000,"Amal Sales Corporation",'WH+RT CURRENT'!$N$2:$N$15000,">365") -> 0 | P10: =SUMIFS('WH+RT CURRENT'!$M$2:$M$15000,'WH+RT CURRENT'!$B$2:$B$15000,"Imp DAP",'WH+RT CURRENT'!$S$2:$S$15000,"Amal Sales Corporation",'WH+RT CURRENT'!$N$2:$N$15000,">365") -> 0 | Q10: =L10+M10+N10+O10 -> 0.901
E11: GRAND TOTAL | F11: =F9+F10 -> 0.155 | G11: =G9+G10 -> 6.096 | H11: =H9+H10 -> 0 | I11: =I9+I10 -> 0 | J11: =J9+J10 -> 0 | K11: =F11+G11+H11+I11 -> 6.251 | L11: =L9+L10 -> 0.335 | M11: =M9+M10 -> 6.046 | N11: =N9+N10 -> 0 | O11: =O9+O10 -> 0 | P11: =P9+P10 -> 0 | Q11: =L11+M11+N11+O11 -> 6.381
E12: TOTAL STOCK | F12: =SUMIFS('WH+RT PREVIOUS'!$M$2:$M$15000,'WH+RT PREVIOUS'!$B$2:$B$15000,"N.C.Urea(45kg)",'WH+RT PREVIOUS'!$S$2:$S$15000,"Amal Sales Corporation") -> 16.25 | G12: =SUMIFS('WH+RT PREVIOUS'!$M$2:$M$15000,'WH+RT PREVIOUS'!$B$2:$B$15000,"15-15-15",'WH+RT PREVIOUS'!$S$2:$S$15000,"Amal Sales Corporation") -> 27.616 | H12: =SUMIFS('WH+RT PREVIOUS'!$M$2:$M$15000,'WH+RT PREVIOUS'!$B$2:$B$15000,"Imp 10-26-26",'WH+RT PREVIOUS'!$S$2:$S$15000,"Amal Sales Corporation") -> 4.5 | I12: =SUMIFS('WH+RT PREVIOUS'!$M$2:$M$15000,'WH+RT PREVIOUS'!$B$2:$B$15000,"MOP",'WH+RT PREVIOUS'!$S$2:$S$15000,"Amal Sales Corporation") -> 8.35 | J12: =SUMIFS('WH+RT PREVIOUS'!$M$2:$M$15000,'WH+RT PREVIOUS'!$B$2:$B$15000,"Imp DAP",'WH+RT PREVIOUS'!$S$2:$S$15000,"Amal Sales Corporation") -> 0 | K12: =F12+G12+H12+I12 -> 56.716 | L12: =SUMIFS('WH+RT CURRENT'!$M$2:$M$15000,'WH+RT CURRENT'!$B$2:$B$15000,"N.C.Urea(45kg)",'WH+RT CURRENT'!$S$2:$S$15000,"Amal Sales Corporation") -> 21.65 | M12: =SUMIFS('WH+RT CURRENT'!$M$2:$M$15000,'WH+RT CURRENT'!$B$2:$B$15000,"15-15-15",'WH+RT CURRENT'!$S$2:$S$15000,"Amal Sales Corporation") -> 23.966 | N12: =SUMIFS('WH+RT CURRENT'!$M$2:$M$15000,'WH+RT CURRENT'!$B$2:$B$15000,"Imp 10-26-26",'WH+RT CURRENT'!$S$2:$S$15000,"Amal Sales Corporation") -> 7.5 | O12: =SUMIFS('WH+RT CURRENT'!$M$2:$M$15000,'WH+RT CURRENT'!$B$2:$B$15000,"MOP",'WH+RT CURRENT'!$S$2:$S$15000,"Amal Sales Corporation") -> 8.35 | P12: =SUMIFS('WH+RT CURRENT'!$M$2:$M$15000,'WH+RT CURRENT'!$B$2:$B$15000,"imp DAP",'WH+RT CURRENT'!$S$2:$S$15000,"Amal Sales Corporation") -> 0 | Q12: =L12+M12+N12+O12 -> 61.466
E15: B K ROY
F16: Previous | L16: Current
F17: UREA | G17: S-15 | H17: 10-26-26 | I17: MOP | J17: DAP | K17: TOTAL | L17: UREA | M17: S-15 | N17: 10-26-26 | O17: MOP | P17: DAP | Q17: TOTAL
E18: 181-365 | F18: =SUMIFS('WH+RT PREVIOUS'!$M$2:$M$15000,'WH+RT PREVIOUS'!$B$2:$B$15000,"N.C.Urea(45kg)",'WH+RT PREVIOUS'!$S$2:$S$15000,"B K ROY AND COMPANY",'WH+RT PREVIOUS'!$N$2:$N$15000,">179",'WH+RT PREVIOUS'!$N$2:$N$15000,"<366") -> 3.062 | G18: =SUMIFS('WH+RT PREVIOUS'!$M$2:$M$15000,'WH+RT PREVIOUS'!$B$2:$B$15000,"15-15-15",'WH+RT PREVIOUS'!$S$2:$S$15000,"B K ROY AND COMPANY",'WH+RT PREVIOUS'!$N$2:$N$15000,">179",'WH+RT PREVIOUS'!$N$2:$N$15000,"<366") -> 1.9 | H18: =SUMIFS('WH+RT PREVIOUS'!$M$2:$M$15000,'WH+RT PREVIOUS'!$B$2:$B$15000,"Imp 10-26-26",'WH+RT PREVIOUS'!$S$2:$S$15000,"B K ROY AND COMPANY",'WH+RT PREVIOUS'!$N$2:$N$15000,">179",'WH+RT PREVIOUS'!$N$2:$N$15000,"<366") -> 0 | I18: =SUMIFS('WH+RT PREVIOUS'!$M$2:$M$15000,'WH+RT PREVIOUS'!$B$2:$B$15000,"MOP",'WH+RT PREVIOUS'!$S$2:$S$15000,"B K ROY AND COMPANY",'WH+RT PREVIOUS'!$N$2:$N$15000,">179",'WH+RT PREVIOUS'!$N$2:$N$15000,"<366") -> 0 | J18: =SUMIFS('WH+RT PREVIOUS'!$M$2:$M$15000,'WH+RT PREVIOUS'!$B$2:$B$15000,"Imp DAP",'WH+RT PREVIOUS'!$S$2:$S$15000,"B K ROY AND COMPANY",'WH+RT PREVIOUS'!$N$2:$N$15000,">179",'WH+RT PREVIOUS'!$N$2:$N$15000,"<366") -> 0 | K18: =F18+G18+H18+I18 -> 4.962 | L18: =SUMIFS('WH+RT CURRENT'!$M$2:$M$15000,'WH+RT CURRENT'!$B$2:$B$15000,"N.C.Urea(45kg)",'WH+RT CURRENT'!$S$2:$S$15000,"B K ROY AND COMPANY",'WH+RT CURRENT'!$N$2:$N$15000,">179",'WH+RT CURRENT'!$N$2:$N$15000,"<366") -> 3.062 | M18: =SUMIFS('WH+RT CURRENT'!$M$2:$M$15000,'WH+RT CURRENT'!$B$2:$B$15000,"15-15-15",'WH+RT CURRENT'!$S$2:$S$15000,"B K ROY AND COMPANY",'WH+RT CURRENT'!$N$2:$N$15000,">179",'WH+RT CURRENT'!$N$2:$N$15000,"<366") -> 1.9 | N18: =SUMIFS('WH+RT CURRENT'!$M$2:$M$15000,'WH+RT CURRENT'!$B$2:$B$15000,"Imp 10-26-26",'WH+RT CURRENT'!$S$2:$S$15000,"B K ROY AND COMPANY",'WH+RT CURRENT'!$N$2:$N$15000,">179",'WH+RT CURRENT'!$N$2:$N$15000,"<366") -> 0 | O18: =SUMIFS('WH+RT CURRENT'!$M$2:$M$15000,'WH+RT CURRENT'!$B$2:$B$15000,"MOP",'WH+RT CURRENT'!$S$2:$S$15000,"B K ROY AND COMPANY",'WH+RT CURRENT'!$N$2:$N$15000,">179",'WH+RT CURRENT'!$N$2:$N$15000,"<366") -> 0 | P18: =SUMIFS('WH+RT CURRENT'!$M$2:$M$15000,'WH+RT CURRENT'!$B$2:$B$15000,"Imp DAP",'WH+RT CURRENT'!$S$2:$S$15000,"B K ROY AND COMPANY",'WH+RT CURRENT'!$N$2:$N$15000,">179",'WH+RT CURRENT'!$N$2:$N$15000,"<366") -> 0 | Q18: =L18+M18+N18+O18 -> 4.962
E19: 366+ | F19: =SUMIFS('WH+RT PREVIOUS'!$M$2:$M$15000,'WH+RT PREVIOUS'!$B$2:$B$15000,"N.C.Urea(45kg)",'WH+RT PREVIOUS'!$S$2:$S$15000,"B K ROY AND COMPANY",'WH+RT PREVIOUS'!$N$2:$N$15000,">365") -> 0 | G19: =SUMIFS('WH+RT PREVIOUS'!$M$2:$M$15000,'WH+RT PREVIOUS'!$B$2:$B$15000,"15-15-15",'WH+RT PREVIOUS'!$S$2:$S$15000,"B K ROY AND COMPANY",'WH+RT PREVIOUS'!$N$2:$N$15000,">365") -> 0 | H19: =SUMIFS('WH+RT PREVIOUS'!$M$2:$M$15000,'WH+RT PREVIOUS'!$B$2:$B$15000,"Imp 10-26-26",'WH+RT PREVIOUS'!$S$2:$S$15000,"B K ROY AND COMPANY",'WH+RT PREVIOUS'!$N$2:$N$15000,">365") -> 0 | I19: =SUMIFS('WH+RT PREVIOUS'!$M$2:$M$15000,'WH+RT PREVIOUS'!$B$2:$B$15000,"MOP",'WH+RT PREVIOUS'!$S$2:$S$15000,"B K ROY AND COMPANY",'WH+RT PREVIOUS'!$N$2:$N$15000,">365") -> 0 | J19: =SUMIFS('WH+RT PREVIOUS'!$M$2:$M$15000,'WH+RT PREVIOUS'!$B$2:$B$15000,"Imp DAP",'WH+RT PREVIOUS'!$S$2:$S$15000,"B K ROY AND COMPANY",'WH+RT PREVIOUS'!$N$2:$N$15000,">365") -> 0 | K19: =F19+G19+H19+I19 -> 0 | L19: =SUMIFS('WH+RT CURRENT'!$M$2:$M$15000,'WH+RT CURRENT'!$B$2:$B$15000,"N.C.Urea(45kg)",'WH+RT CURRENT'!$S$2:$S$15000,"B K ROY AND COMPANY",'WH+RT CURRENT'!$N$2:$N$15000,">365") -> 0 | M19: =SUMIFS('WH+RT CURRENT'!$M$2:$M$15000,'WH+RT CURRENT'!$B$2:$B$15000,"15-15-15",'WH+RT CURRENT'!$S$2:$S$15000,"B K ROY AND COMPANY",'WH+RT CURRENT'!$N$2:$N$15000,">365") -> 0 | N19: =SUMIFS('WH+RT CURRENT'!$M$2:$M$15000,'WH+RT CURRENT'!$B$2:$B$15000,"Imp 10-26-26",'WH+RT CURRENT'!$S$2:$S$15000,"B K ROY AND COMPANY",'WH+RT CURRENT'!$N$2:$N$15000,">365") -> 0 | O19: =SUMIFS('WH+RT CURRENT'!$M$2:$M$15000,'WH+RT CURRENT'!$B$2:$B$15000,"MOP",'WH+RT CURRENT'!$S$2:$S$15000,"B K ROY AND COMPANY",'WH+RT CURRENT'!$N$2:$N$15000,">365") -> 0 | P19: =SUMIFS('WH+RT CURRENT'!$M$2:$M$15000,'WH+RT CURRENT'!$B$2:$B$15000,"Imp DAP",'WH+RT CURRENT'!$S$2:$S$15000,"B K ROY AND COMPANY",'WH+RT CURRENT'!$N$2:$N$15000,">365") -> 0 | Q19: =L19+M19+N19+O19 -> 0
E20: GRAND TOTAL | F20: =F18+F19 -> 3.062 | G20: =G18+G19 -> 1.9 | H20: =H18+H19 -> 0 | I20: =I18+I19 -> 0 | J20: =J18+J19 -> 0 | K20: =F20+G20+H20+I20 -> 4.962 | L20: =L18+L19 -> 3.062 | M20: =M18+M19 -> 1.9 | N20: =N18+N19 -> 0 | O20: =O18+O19 -> 0 | P20: =P18+P19 -> 0 | Q20: =L20+M20+N20+O20 -> 4.962
E21: TOTAL STOCK | F21: =SUMIFS('WH+RT PREVIOUS'!$M$2:$M$15000,'WH+RT PREVIOUS'!$B$2:$B$15000,"N.C.Urea(45kg)",'WH+RT PREVIOUS'!$S$2:$S$15000,"B K ROY AND COMPANY") -> 61.812 | G21: =SUMIFS('WH+RT PREVIOUS'!$M$2:$M$15000,'WH+RT PREVIOUS'!$B$2:$B$15000,"15-15-15",'WH+RT PREVIOUS'!$S$2:$S$15000,"B K ROY AND COMPANY") -> 43.925 | H21: =SUMIFS('WH+RT PREVIOUS'!$M$2:$M$15000,'WH+RT PREVIOUS'!$B$2:$B$15000,"Imp 10-26-26",'WH+RT PREVIOUS'!$S$2:$S$15000,"B K ROY AND COMPANY") -> 19.65 | I21: =SUMIFS('WH+RT PREVIOUS'!$M$2:$M$15000,'WH+RT PREVIOUS'!$B$2:$B$15000,"MOP",'WH+RT PREVIOUS'!$S$2:$S$15000,"B K ROY AND COMPANY") -> 15.4 | J21: =SUMIFS('WH+RT PREVIOUS'!$M$2:$M$15000,'WH+RT PREVIOUS'!$B$2:$B$15000,"Imp DAP",'WH+RT PREVIOUS'!$S$2:$S$15000,"B K ROY AND COMPANY") -> 0 | K21: =F21+G21+H21+I21 -> 140.787 | L21: =SUMIFS('WH+RT CURRENT'!$M$2:$M$15000,'WH+RT CURRENT'!$B$2:$B$15000,"N.C.Urea(45kg)",'WH+RT CURRENT'!$S$2:$S$15000,"B K ROY AND COMPANY") -> 60.357 | M21: =SUMIFS('WH+RT CURRENT'!$M$2:$M$15000,'WH+RT CURRENT'!$B$2:$B$15000,"15-15-15",'WH+RT CURRENT'!$S$2:$S$15000,"B K ROY AND COMPANY") -> 33.85 | N21: =SUMIFS('WH+RT CURRENT'!$M$2:$M$15000,'WH+RT CURRENT'!$B$2:$B$15000,"Imp 10-26-26",'WH+RT CURRENT'!$S$2:$S$15000,"B K ROY AND COMPANY") -> 18.8 | O21: =SUMIFS('WH+RT CURRENT'!$M$2:$M$15000,'WH+RT CURRENT'!$B$2:$B$15000,"MOP",'WH+RT CURRENT'!$S$2:$S$15000,"B K ROY AND COMPANY") -> 14.95 | P21: =SUMIFS('WH+RT CURRENT'!$M$2:$M$15000,'WH+RT CURRENT'!$B$2:$B$15000,"Imp DAP",'WH+RT CURRENT'!$S$2:$S$15000,"B K ROY AND COMPANY") -> 0 | Q21: =L21+M21+N21+O21 -> 127.957
E24: BARASAT KRISHI BIPANI
F25: Previous | L25: Current
F26: UREA | G26: S-15 | H26: 10-26-26 | I26: MOP | J26: DAP | K26: TOTAL | L26: UREA | M26: S-15 | N26: 10-26-26 | O26: MOP | P26: DAP | Q26: TOTAL
E27: 181-365 | F27: =SUMIFS('WH+RT PREVIOUS'!$M$2:$M$15000,'WH+RT PREVIOUS'!$B$2:$B$15000,"N.C.Urea(45kg)",'WH+RT PREVIOUS'!$S$2:$S$15000,"Barasat Krishi Bipani",'WH+RT PREVIOUS'!$N$2:$N$15000,">179",'WH+RT PREVIOUS'!$N$2:$N$15000,"<366") -> 0 | G27: =SUMIFS('WH+RT PREVIOUS'!$M$2:$M$15000,'WH+RT PREVIOUS'!$B$2:$B$15000,"15-15-15",'WH+RT PREVIOUS'!$S$2:$S$15000,"Barasat Krishi Bipani",'WH+RT PREVIOUS'!$N$2:$N$15000,">179",'WH+RT PREVIOUS'!$N$2:$N$15000,"<366") -> 0.747 | H27: =SUMIFS('WH+RT PREVIOUS'!$M$2:$M$15000,'WH+RT PREVIOUS'!$B$2:$B$15000,"Imp 10-26-26",'WH+RT PREVIOUS'!$S$2:$S$15000,"Barasat Krishi Bipani",'WH+RT PREVIOUS'!$N$2:$N$15000,">179",'WH+RT PREVIOUS'!$N$2:$N$15000,"<366") -> 0 | I27: =SUMIFS('WH+RT PREVIOUS'!$M$2:$M$15000,'WH+RT PREVIOUS'!$B$2:$B$15000,"MOP",'WH+RT PREVIOUS'!$S$2:$S$15000,"Barasat Krishi Bipani",'WH+RT PREVIOUS'!$N$2:$N$15000,">179",'WH+RT PREVIOUS'!$N$2:$N$15000,"<366") -> 0 | J27: =SUMIFS('WH+RT PREVIOUS'!$M$2:$M$15000,'WH+RT PREVIOUS'!$B$2:$B$15000,"Imp DAP",'WH+RT PREVIOUS'!$S$2:$S$15000,"Barasat Krishi Bipani",'WH+RT PREVIOUS'!$N$2:$N$15000,">179",'WH+RT PREVIOUS'!$N$2:$N$15000,"<366") -> 0 | K27: =F27+G27+H27+I27 -> 0.747 | L27: =SUMIFS('WH+RT CURRENT'!$M$2:$M$15000,'WH+RT CURRENT'!$B$2:$B$15000,"N.C.Urea(45kg)",'WH+RT CURRENT'!$S$2:$S$15000,"Barasat Krishi Bipani",'WH+RT CURRENT'!$N$2:$N$15000,">179",'WH+RT CURRENT'!$N$2:$N$15000,"<366") -> 0 | M27: =SUMIFS('WH+RT CURRENT'!$M$2:$M$15000,'WH+RT CURRENT'!$B$2:$B$15000,"15-15-15",'WH+RT CURRENT'!$S$2:$S$15000,"Barasat Krishi Bipani",'WH+RT CURRENT'!$N$2:$N$15000,">179",'WH+RT CURRENT'!$N$2:$N$15000,"<366") -> 0.697 | N27: =SUMIFS('WH+RT CURRENT'!$M$2:$M$15000,'WH+RT CURRENT'!$B$2:$B$15000,"Imp 10-26-26",'WH+RT CURRENT'!$S$2:$S$15000,"Barasat Krishi Bipani",'WH+RT CURRENT'!$N$2:$N$15000,">179",'WH+RT CURRENT'!$N$2:$N$15000,"<366") -> 0 | O27: =SUMIFS('WH+RT CURRENT'!$M$2:$M$15000,'WH+RT CURRENT'!$B$2:$B$15000,"MOP",'WH+RT CURRENT'!$S$2:$S$15000,"Barasat Krishi Bipani",'WH+RT CURRENT'!$N$2:$N$15000,">179",'WH+RT CURRENT'!$N$2:$N$15000,"<366") -> 0 | P27: =SUMIFS('WH+RT CURRENT'!$M$2:$M$15000,'WH+RT CURRENT'!$B$2:$B$15000,"Imp DAP",'WH+RT CURRENT'!$S$2:$S$15000,"Barasat Krishi Bipani",'WH+RT CURRENT'!$N$2:$N$15000,">179",'WH+RT CURRENT'!$N$2:$N$15000,"<366") -> 0 | Q27: =L27+M27+N27+O27 -> 0.697
E28: 366+ | F28: =SUMIFS('WH+RT PREVIOUS'!$M$2:$M$15000,'WH+RT PREVIOUS'!$B$2:$B$15000,"N.C.Urea(45kg)",'WH+RT PREVIOUS'!$S$2:$S$15000,"Barasat Krishi Bipani",'WH+RT PREVIOUS'!$N$2:$N$15000,">365") -> 0.765 | G28: =SUMIFS('WH+RT PREVIOUS'!$M$2:$M$15000,'WH+RT PREVIOUS'!$B$2:$B$15000,"15-15-15",'WH+RT PREVIOUS'!$S$2:$S$15000,"Barasat Krishi Bipani",'WH+RT PREVIOUS'!$N$2:$N$15000,">365") -> 1.423 | H28: =SUMIFS('WH+RT PREVIOUS'!$M$2:$M$15000,'WH+RT PREVIOUS'!$B$2:$B$15000,"Imp 10-26-26",'WH+RT PREVIOUS'!$S$2:$S$15000,"Barasat Krishi Bipani",'WH+RT PREVIOUS'!$N$2:$N$15000,">365") -> 0 | I28: =SUMIFS('WH+RT PREVIOUS'!$M$2:$M$15000,'WH+RT PREVIOUS'!$B$2:$B$15000,"MOP",'WH+RT PREVIOUS'!$S$2:$S$15000,"Barasat Krishi Bipani",'WH+RT PREVIOUS'!$N$2:$N$15000,">365") -> 0 | J28: =SUMIFS('WH+RT PREVIOUS'!$M$2:$M$15000,'WH+RT PREVIOUS'!$B$2:$B$15000,"Imp DAP",'WH+RT PREVIOUS'!$S$2:$S$15000,"Barasat Krishi Bipani",'WH+RT PREVIOUS'!$N$2:$N$15000,">365") -> 0 | K28: =F28+G28+H28+I28 -> 2.188 | L28: =SUMIFS('WH+RT CURRENT'!$M$2:$M$15000,'WH+RT CURRENT'!$B$2:$B$15000,"N.C.Urea(45kg)",'WH+RT CURRENT'!$S$2:$S$15000,"Barasat Krishi Bipani",'WH+RT CURRENT'!$N$2:$N$15000,">365") -> 0.765 | M28: =SUMIFS('WH+RT CURRENT'!$M$2:$M$15000,'WH+RT CURRENT'!$B$2:$B$15000,"15-15-15",'WH+RT CURRENT'!$S$2:$S$15000,"Barasat Krishi Bipani",'WH+RT CURRENT'!$N$2:$N$15000,">365") -> 1.423 | N28: =SUMIFS('WH+RT CURRENT'!$M$2:$M$15000,'WH+RT CURRENT'!$B$2:$B$15000,"Imp 10-26-26",'WH+RT CURRENT'!$S$2:$S$15000,"Barasat Krishi Bipani",'WH+RT CURRENT'!$N$2:$N$15000,">365") -> 0 | O28: =SUMIFS('WH+RT CURRENT'!$M$2:$M$15000,'WH+RT CURRENT'!$B$2:$B$15000,"MOP",'WH+RT CURRENT'!$S$2:$S$15000,"Barasat Krishi Bipani",'WH+RT CURRENT'!$N$2:$N$15000,">365") -> 0 | P28: =SUMIFS('WH+RT CURRENT'!$M$2:$M$15000,'WH+RT CURRENT'!$B$2:$B$15000,"Imp DAP",'WH+RT CURRENT'!$S$2:$S$15000,"Barasat Krishi Bipani",'WH+RT CURRENT'!$N$2:$N$15000,">365") -> 0 | Q28: =L28+M28+N28+O28 -> 2.188
E29: GRAND TOTAL | F29: =F27+F28 -> 0.765 | G29: =G27+G28 -> 2.17 | H29: =H27+H28 -> 0 | I29: =I27+I28 -> 0 | J29: =J27+J28 -> 0 | K29: =F29+G29+H29+I29 -> 2.935 | L29: =L27+L28 -> 0.765 | M29: =M27+M28 -> 2.12 | N29: =N27+N28 -> 0 | O29: =O27+O28 -> 0 | P29: =P27+P28 -> 0 | Q29: =L29+M29+N29+O29 -> 2.885
E30: TOTAL STOCK | F30: =SUMIFS('WH+RT PREVIOUS'!$M$2:$M$15000,'WH+RT PREVIOUS'!$B$2:$B$15000,"N.C.Urea(45kg)",'WH+RT PREVIOUS'!$S$2:$S$15000,"Barasat Krishi Bipani") -> 28.175 | G30: =SUMIFS('WH+RT PREVIOUS'!$M$2:$M$15000,'WH+RT PREVIOUS'!$B$2:$B$15000,"15-15-15",'WH+RT PREVIOUS'!$S$2:$S$15000,"Barasat Krishi Bipani") -> 9.204 | H30: =SUMIFS('WH+RT PREVIOUS'!$M$2:$M$15000,'WH+RT PREVIOUS'!$B$2:$B$15000,"Imp 10-26-26",'WH+RT PREVIOUS'!$S$2:$S$15000,"Barasat Krishi Bipani") -> 6.237 | I30: =SUMIFS('WH+RT PREVIOUS'!$M$2:$M$15000,'WH+RT PREVIOUS'!$B$2:$B$15000,"MOP",'WH+RT PREVIOUS'!$S$2:$S$15000,"Barasat Krishi Bipani") -> 0.05 | J30: =SUMIFS('WH+RT PREVIOUS'!$M$2:$M$15000,'WH+RT PREVIOUS'!$B$2:$B$15000,"Imp DAP",'WH+RT PREVIOUS'!$S$2:$S$15000,"Barasat Krishi Bipani") -> 0 | K30: =F30+G30+H30+I30 -> 43.666 | L30: =SUMIFS('WH+RT CURRENT'!$M$2:$M$15000,'WH+RT CURRENT'!$B$2:$B$15000,"N.C.Urea(45kg)",'WH+RT CURRENT'!$S$2:$S$15000,"Barasat Krishi Bipani") -> 23.76 | M30: =SUMIFS('WH+RT CURRENT'!$M$2:$M$15000,'WH+RT CURRENT'!$B$2:$B$15000,"15-15-15",'WH+RT CURRENT'!$S$2:$S$15000,"Barasat Krishi Bipani") -> 8.854 | N30: =SUMIFS('WH+RT CURRENT'!$M$2:$M$15000,'WH+RT CURRENT'!$B$2:$B$15000,"Imp 10-26-26",'WH+RT CURRENT'!$S$2:$S$15000,"Barasat Krishi Bipani") -> 6.037 | O30: =SUMIFS('WH+RT CURRENT'!$M$2:$M$15000,'WH+RT CURRENT'!$B$2:$B$15000,"MOP",'WH+RT CURRENT'!$S$2:$S$15000,"Barasat Krishi Bipani") -> 0 | P30: =SUMIFS('WH+RT CURRENT'!$M$2:$M$15000,'WH+RT CURRENT'!$B$2:$B$15000,"Imp DAP",'WH+RT CURRENT'!$S$2:$S$15000,"Barasat Krishi Bipani") -> 0 | Q30: =L30+M30+N30+O30 -> 38.651
E33: C R DEY
F34: Previous | L34: Current
F35: UREA | G35: S-15 | H35: 10-26-26 | I35: MOP | J35: DAP | K35: TOTAL | L35: UREA | M35: S-15 | N35: 10-26-26 | O35: MOP | P35: DAP | Q35: TOTAL
E36: 181-365 | F36: =SUMIFS('WH+RT PREVIOUS'!$M$2:$M$15000,'WH+RT PREVIOUS'!$B$2:$B$15000,"N.C.Urea(45kg)",'WH+RT PREVIOUS'!$S$2:$S$15000,"Chitta Ranjan Dey",'WH+RT PREVIOUS'!$N$2:$N$15000,">179",'WH+RT PREVIOUS'!$N$2:$N$15000,"<366") -> 9.675 | G36: =SUMIFS('WH+RT PREVIOUS'!$M$2:$M$15000,'WH+RT PREVIOUS'!$B$2:$B$15000,"15-15-15",'WH+RT PREVIOUS'!$S$2:$S$15000,"Chitta Ranjan Dey",'WH+RT PREVIOUS'!$N$2:$N$15000,">179",'WH+RT PREVIOUS'!$N$2:$N$15000,"<366") -> 5.139 | H36: =SUMIFS('WH+RT PREVIOUS'!$M$2:$M$15000,'WH+RT PREVIOUS'!$B$2:$B$15000,"Imp 10-26-26",'WH+RT PREVIOUS'!$S$2:$S$15000,"Chitta Ranjan Dey",'WH+RT PREVIOUS'!$N$2:$N$15000,">179",'WH+RT PREVIOUS'!$N$2:$N$15000,"<366") -> 2.1 | I36: =SUMIFS('WH+RT PREVIOUS'!$M$2:$M$15000,'WH+RT PREVIOUS'!$B$2:$B$15000,"MOP",'WH+RT PREVIOUS'!$S$2:$S$15000,"Chitta Ranjan Dey",'WH+RT PREVIOUS'!$N$2:$N$15000,">179",'WH+RT PREVIOUS'!$N$2:$N$15000,"<366") -> 0 | J36: =SUMIFS('WH+RT PREVIOUS'!$M$2:$M$15000,'WH+RT PREVIOUS'!$B$2:$B$15000,"Imp DAP",'WH+RT PREVIOUS'!$S$2:$S$15000,"Chitta Ranjan Dey",'WH+RT PREVIOUS'!$N$2:$N$15000,">179",'WH+RT PREVIOUS'!$N$2:$N$15000,"<366") -> 0 | K36: =F36+G36+H36+I36 -> 16.914 | L36: =SUMIFS('WH+RT CURRENT'!$M$2:$M$15000,'WH+RT CURRENT'!$B$2:$B$15000,"N.C.Urea(45kg)",'WH+RT CURRENT'!$S$2:$S$15000,"Chitta Ranjan Dey",'WH+RT CURRENT'!$N$2:$N$15000,">179",'WH+RT CURRENT'!$N$2:$N$15000,"<366") -> 12.33 | M36: =SUMIFS('WH+RT CURRENT'!$M$2:$M$15000,'WH+RT CURRENT'!$B$2:$B$15000,"15-15-15",'WH+RT CURRENT'!$S$2:$S$15000,"Chitta Ranjan Dey",'WH+RT CURRENT'!$N$2:$N$15000,">179",'WH+RT CURRENT'!$N$2:$N$15000,"<366") -> 11.44 | N36: =SUMIFS('WH+RT CURRENT'!$M$2:$M$15000,'WH+RT CURRENT'!$B$2:$B$15000,"Imp 10-26-26",'WH+RT CURRENT'!$S$2:$S$15000,"Chitta Ranjan Dey",'WH+RT CURRENT'!$N$2:$N$15000,">179",'WH+RT CURRENT'!$N$2:$N$15000,"<366") -> 0.2 | O36: =SUMIFS('WH+RT CURRENT'!$M$2:$M$15000,'WH+RT CURRENT'!$B$2:$B$15000,"MOP",'WH+RT CURRENT'!$S$2:$S$15000,"Chitta Ranjan Dey",'WH+RT CURRENT'!$N$2:$N$15000,">179",'WH+RT CURRENT'!$N$2:$N$15000,"<366") -> 0 | P36: =SUMIFS('WH+RT CURRENT'!$M$2:$M$15000,'WH+RT CURRENT'!$B$2:$B$15000,"Imp DAP",'WH+RT CURRENT'!$S$2:$S$15000,"Chitta Ranjan Dey",'WH+RT CURRENT'!$N$2:$N$15000,">179",'WH+RT CURRENT'!$N$2:$N$15000,"<366") -> 0 | Q36: =L36+M36+N36+O36 -> 23.97
E37: 366+ | F37: =SUMIFS('WH+RT PREVIOUS'!$M$2:$M$15000,'WH+RT PREVIOUS'!$B$2:$B$15000,"N.C.Urea(45kg)",'WH+RT PREVIOUS'!$S$2:$S$15000,"Chitta Ranjan Dey",'WH+RT PREVIOUS'!$N$2:$N$15000,">365") -> 21.579 | G37: =SUMIFS('WH+RT PREVIOUS'!$M$2:$M$15000,'WH+RT PREVIOUS'!$B$2:$B$15000,"15-15-15",'WH+RT PREVIOUS'!$S$2:$S$15000,"Chitta Ranjan Dey",'WH+RT PREVIOUS'!$N$2:$N$15000,">365") -> 7.035 | H37: =SUMIFS('WH+RT PREVIOUS'!$M$2:$M$15000,'WH+RT PREVIOUS'!$B$2:$B$15000,"Imp 10-26-26",'WH+RT PREVIOUS'!$S$2:$S$15000,"Chitta Ranjan Dey",'WH+RT PREVIOUS'!$N$2:$N$15000,">365") -> 0 | I37: =SUMIFS('WH+RT PREVIOUS'!$M$2:$M$15000,'WH+RT PREVIOUS'!$B$2:$B$15000,"MOP",'WH+RT PREVIOUS'!$S$2:$S$15000,"Chitta Ranjan Dey",'WH+RT PREVIOUS'!$N$2:$N$15000,">365") -> 0 | J37: =SUMIFS('WH+RT PREVIOUS'!$M$2:$M$15000,'WH+RT PREVIOUS'!$B$2:$B$15000,"Imp DAP",'WH+RT PREVIOUS'!$S$2:$S$15000,"Chitta Ranjan Dey",'WH+RT PREVIOUS'!$N$2:$N$15000,">365") -> 0 | K37: =F37+G37+H37+I37 -> 28.614 | L37: =SUMIFS('WH+RT CURRENT'!$M$2:$M$15000,'WH+RT CURRENT'!$B$2:$B$15000,"N.C.Urea(45kg)",'WH+RT CURRENT'!$S$2:$S$15000,"Chitta Ranjan Dey",'WH+RT CURRENT'!$N$2:$N$15000,">365") -> 21.579 | M37: =SUMIFS('WH+RT CURRENT'!$M$2:$M$15000,'WH+RT CURRENT'!$B$2:$B$15000,"15-15-15",'WH+RT CURRENT'!$S$2:$S$15000,"Chitta Ranjan Dey",'WH+RT CURRENT'!$N$2:$N$15000,">365") -> 7.035 | N37: =SUMIFS('WH+RT CURRENT'!$M$2:$M$15000,'WH+RT CURRENT'!$B$2:$B$15000,"Imp 10-26-26",'WH+RT CURRENT'!$S$2:$S$15000,"Chitta Ranjan Dey",'WH+RT CURRENT'!$N$2:$N$15000,">365") -> 0 | O37: =SUMIFS('WH+RT CURRENT'!$M$2:$M$15000,'WH+RT CURRENT'!$B$2:$B$15000,"MOP",'WH+RT CURRENT'!$S$2:$S$15000,"Chitta Ranjan Dey",'WH+RT CURRENT'!$N$2:$N$15000,">365") -> 0 | P37: =SUMIFS('WH+RT CURRENT'!$M$2:$M$15000,'WH+RT CURRENT'!$B$2:$B$15000,"Imp DAP",'WH+RT CURRENT'!$S$2:$S$15000,"Chitta Ranjan Dey",'WH+RT CURRENT'!$N$2:$N$15000,">365") -> 0 | Q37: =L37+M37+N37+O37 -> 28.614
E38: GRAND TOTAL | F38: =F36+F37 -> 31.254 | G38: =G36+G37 -> 12.174 | H38: =H36+H37 -> 2.1 | I38: =I36+I37 -> 0 | J38: =J36+J37 -> 0 | K38: =F38+G38+H38+I38 -> 45.528 | L38: =L36+L37 -> 33.909 | M38: =M36+M37 -> 18.475 | N38: =N36+N37 -> 0.2 | O38: =O36+O37 -> 0 | P38: =P36+P37 -> 0 | Q38: =L38+M38+N38+O38 -> 52.584
E39: TOTAL STOCK | F39: =SUMIFS('WH+RT PREVIOUS'!$M$2:$M$15000,'WH+RT PREVIOUS'!$B$2:$B$15000,"N.C.Urea(45kg)",'WH+RT PREVIOUS'!$S$2:$S$15000,"Chitta Ranjan Dey") -> 706.064 | G39: =SUMIFS('WH+RT PREVIOUS'!$M$2:$M$15000,'WH+RT PREVIOUS'!$B$2:$B$15000,"15-15-15",'WH+RT PREVIOUS'!$S$2:$S$15000,"Chitta Ranjan Dey") -> 244.612 | H39: =SUMIFS('WH+RT PREVIOUS'!$M$2:$M$15000,'WH+RT PREVIOUS'!$B$2:$B$15000,"Imp 10-26-26",'WH+RT PREVIOUS'!$S$2:$S$15000,"Chitta Ranjan Dey") -> 215.45 | I39: =SUMIFS('WH+RT PREVIOUS'!$M$2:$M$15000,'WH+RT PREVIOUS'!$B$2:$B$15000,"MOP",'WH+RT PREVIOUS'!$S$2:$S$15000,"Chitta Ranjan Dey") -> 235.66 | J39: =SUMIFS('WH+RT PREVIOUS'!$M$2:$M$15000,'WH+RT PREVIOUS'!$B$2:$B$15000,"Imp DAP",'WH+RT PREVIOUS'!$S$2:$S$15000,"Chitta Ranjan Dey") -> 0 | K39: =F39+G39+H39+I39 -> 1401.786 | L39: =SUMIFS('WH+RT CURRENT'!$M$2:$M$15000,'WH+RT CURRENT'!$B$2:$B$15000,"N.C.Urea(45kg)",'WH+RT CURRENT'!$S$2:$S$15000,"Chitta Ranjan Dey") -> 726.214 | M39: =SUMIFS('WH+RT CURRENT'!$M$2:$M$15000,'WH+RT CURRENT'!$B$2:$B$15000,"15-15-15",'WH+RT CURRENT'!$S$2:$S$15000,"Chitta Ranjan Dey") -> 208.113 | N39: =SUMIFS('WH+RT CURRENT'!$M$2:$M$15000,'WH+RT CURRENT'!$B$2:$B$15000,"Imp 10-26-26",'WH+RT CURRENT'!$S$2:$S$15000,"Chitta Ranjan Dey") -> 189.9 | O39: =SUMIFS('WH+RT CURRENT'!$M$2:$M$15000,'WH+RT CURRENT'!$B$2:$B$15000,"MOP",'WH+RT CURRENT'!$S$2:$S$15000,"Chitta Ranjan Dey") -> 217.31 | P39: =SUMIFS('WH+RT CURRENT'!$M$2:$M$15000,'WH+RT CURRENT'!$B$2:$B$15000,"Imp DAP",'WH+RT CURRENT'!$S$2:$S$15000,"Chitta Ranjan Dey") -> 0 | Q39: =L39+M39+N39+O39 -> 1341.537
E42: M.K. Chemical and Fertilizers
F43: Previous | L43: Current
F44: UREA | G44: S-15 | H44: 10-26-26 | I44: MOP | J44: DAP | K44: TOTAL | L44: UREA | M44: S-15 | N44: 10-26-26 | O44: MOP | P44: DAP | Q44: TOTAL
E45: 181-365 | F45: =SUMIFS('WH+RT PREVIOUS'!$M$2:$M$15000,'WH+RT PREVIOUS'!$B$2:$B$15000,"N.C.Urea(45kg)",'WH+RT PREVIOUS'!$S$2:$S$15000,"M.K. Chemical and Fertilizers",'WH+RT PREVIOUS'!$N$2:$N$15000,">179",'WH+RT PREVIOUS'!$N$2:$N$15000,"<366") -> 3.96 | G45: =SUMIFS('WH+RT PREVIOUS'!$M$2:$M$15000,'WH+RT PREVIOUS'!$B$2:$B$15000,"15-15-15",'WH+RT PREVIOUS'!$S$2:$S$15000,"M.K. Chemical and Fertilizers",'WH+RT PREVIOUS'!$N$2:$N$15000,">179",'WH+RT PREVIOUS'!$N$2:$N$15000,"<366") -> 4 | H45: =SUMIFS('WH+RT PREVIOUS'!$M$2:$M$15000,'WH+RT PREVIOUS'!$B$2:$B$15000,"Imp 10-26-26",'WH+RT PREVIOUS'!$S$2:$S$15000,"M.K. Chemical and Fertilizers",'WH+RT PREVIOUS'!$N$2:$N$15000,">179",'WH+RT PREVIOUS'!$N$2:$N$15000,"<366") -> 0 | I45: =SUMIFS('WH+RT PREVIOUS'!$M$2:$M$15000,'WH+RT PREVIOUS'!$B$2:$B$15000,"MOP",'WH+RT PREVIOUS'!$S$2:$S$15000,"M.K. Chemical and Fertilizers",'WH+RT PREVIOUS'!$N$2:$N$15000,">179",'WH+RT PREVIOUS'!$N$2:$N$15000,"<366") -> 0 | J45: =SUMIFS('WH+RT PREVIOUS'!$M$2:$M$15000,'WH+RT PREVIOUS'!$B$2:$B$15000,"Imp DAP",'WH+RT PREVIOUS'!$S$2:$S$15000,"M.K. Chemical and Fertilizers",'WH+RT PREVIOUS'!$N$2:$N$15000,">179",'WH+RT PREVIOUS'!$N$2:$N$15000,"<366") -> 0 | K45: =F45+G45+H45+I45 -> 7.96 | L45: =SUMIFS('WH+RT CURRENT'!$M$2:$M$15000,'WH+RT CURRENT'!$B$2:$B$15000,"N.C.Urea(45kg)",'WH+RT CURRENT'!$S$2:$S$15000,"M.K. Chemical and Fertilizers",'WH+RT CURRENT'!$N$2:$N$15000,">179",'WH+RT CURRENT'!$N$2:$N$15000,"<366") -> 3.46 | M45: =SUMIFS('WH+RT CURRENT'!$M$2:$M$15000,'WH+RT CURRENT'!$B$2:$B$15000,"15-15-15",'WH+RT CURRENT'!$S$2:$S$15000,"M.K. Chemical and Fertilizers",'WH+RT CURRENT'!$N$2:$N$15000,">179",'WH+RT CURRENT'!$N$2:$N$15000,"<366") -> 7.45 | N45: =SUMIFS('WH+RT CURRENT'!$M$2:$M$15000,'WH+RT CURRENT'!$B$2:$B$15000,"Imp 10-26-26",'WH+RT CURRENT'!$S$2:$S$15000,"M.K. Chemical and Fertilizers",'WH+RT CURRENT'!$N$2:$N$15000,">179",'WH+RT CURRENT'!$N$2:$N$15000,"<366") -> 0 | O45: =SUMIFS('WH+RT CURRENT'!$M$2:$M$15000,'WH+RT CURRENT'!$B$2:$B$15000,"MOP",'WH+RT CURRENT'!$S$2:$S$15000,"M.K. Chemical and Fertilizers",'WH+RT CURRENT'!$N$2:$N$15000,">179",'WH+RT CURRENT'!$N$2:$N$15000,"<366") -> 0 | P45: =SUMIFS('WH+RT CURRENT'!$M$2:$M$15000,'WH+RT CURRENT'!$B$2:$B$15000,"Imp DAP",'WH+RT CURRENT'!$S$2:$S$15000,"M.K. Chemical and Fertilizers",'WH+RT CURRENT'!$N$2:$N$15000,">179",'WH+RT CURRENT'!$N$2:$N$15000,"<366") -> 0 | Q45: =L45+M45+N45+O45 -> 10.91
E46: 366+ | F46: =SUMIFS('WH+RT PREVIOUS'!$M$2:$M$15000,'WH+RT PREVIOUS'!$B$2:$B$15000,"N.C.Urea(45kg)",'WH+RT PREVIOUS'!$S$2:$S$15000,"M.K. Chemical and Fertilizers",'WH+RT PREVIOUS'!$N$2:$N$15000,">365") -> 16.326 | G46: =SUMIFS('WH+RT PREVIOUS'!$M$2:$M$15000,'WH+RT PREVIOUS'!$B$2:$B$15000,"15-15-15",'WH+RT PREVIOUS'!$S$2:$S$15000,"M.K. Chemical and Fertilizers",'WH+RT PREVIOUS'!$N$2:$N$15000,">365") -> 13.475 | H46: =SUMIFS('WH+RT PREVIOUS'!$M$2:$M$15000,'WH+RT PREVIOUS'!$B$2:$B$15000,"Imp 10-26-26",'WH+RT PREVIOUS'!$S$2:$S$15000,"M.K. Chemical and Fertilizers",'WH+RT PREVIOUS'!$N$2:$N$15000,">365") -> 0 | I46: =SUMIFS('WH+RT PREVIOUS'!$M$2:$M$15000,'WH+RT PREVIOUS'!$B$2:$B$15000,"MOP",'WH+RT PREVIOUS'!$S$2:$S$15000,"M.K. Chemical and Fertilizers",'WH+RT PREVIOUS'!$N$2:$N$15000,">365") -> 0.034 | J46: =SUMIFS('WH+RT PREVIOUS'!$M$2:$M$15000,'WH+RT PREVIOUS'!$B$2:$B$15000,"Imp DAP",'WH+RT PREVIOUS'!$S$2:$S$15000,"M.K. Chemical and Fertilizers",'WH+RT PREVIOUS'!$N$2:$N$15000,">365") -> 0 | K46: =F46+G46+H46+I46 -> 29.835 | L46: =SUMIFS('WH+RT CURRENT'!$M$2:$M$15000,'WH+RT CURRENT'!$B$2:$B$15000,"N.C.Urea(45kg)",'WH+RT CURRENT'!$S$2:$S$15000,"M.K. Chemical and Fertilizers",'WH+RT CURRENT'!$N$2:$N$15000,">365") -> 16.326 | M46: =SUMIFS('WH+RT CURRENT'!$M$2:$M$15000,'WH+RT CURRENT'!$B$2:$B$15000,"15-15-15",'WH+RT CURRENT'!$S$2:$S$15000,"M.K. Chemical and Fertilizers",'WH+RT CURRENT'!$N$2:$N$15000,">365") -> 13.475 | N46: =SUMIFS('WH+RT CURRENT'!$M$2:$M$15000,'WH+RT CURRENT'!$B$2:$B$15000,"Imp 10-26-26",'WH+RT CURRENT'!$S$2:$S$15000,"M.K. Chemical and Fertilizers",'WH+RT CURRENT'!$N$2:$N$15000,">365") -> 0 | O46: =SUMIFS('WH+RT CURRENT'!$M$2:$M$15000,'WH+RT CURRENT'!$B$2:$B$15000,"MOP",'WH+RT CURRENT'!$S$2:$S$15000,"M.K. Chemical and Fertilizers",'WH+RT CURRENT'!$N$2:$N$15000,">365") -> 0.034 | P46: =SUMIFS('WH+RT CURRENT'!$M$2:$M$15000,'WH+RT CURRENT'!$B$2:$B$15000,"Imp DAP",'WH+RT CURRENT'!$S$2:$S$15000,"M.K. Chemical and Fertilizers",'WH+RT CURRENT'!$N$2:$N$15000,">365") -> 0 | Q46: =L46+M46+N46+O46 -> 29.835
E47: GRAND TOTAL | F47: =F45+F46 -> 20.286 | G47: =G45+G46 -> 17.475 | H47: =H45+H46 -> 0 | I47: =I45+I46 -> 0.034 | J47: =J45+J46 -> 0 | K47: =F47+G47+H47+I47 -> 37.795 | L47: =L45+L46 -> 19.786 | M47: =M45+M46 -> 20.925 | N47: =N45+N46 -> 0 | O47: =O45+O46 -> 0.034 | P47: =P45+P46 -> 0 | Q47: =L47+M47+N47+O47 -> 40.745
E48: TOTAL STOCK | F48: =SUMIFS('WH+RT PREVIOUS'!$M$2:$M$15000,'WH+RT PREVIOUS'!$B$2:$B$15000,"N.C.Urea(45kg)",'WH+RT PREVIOUS'!$S$2:$S$15000,"M.K. Chemical and Fertilizers") -> 224.537 | G48: =SUMIFS('WH+RT PREVIOUS'!$M$2:$M$15000,'WH+RT PREVIOUS'!$B$2:$B$15000,"15-15-15",'WH+RT PREVIOUS'!$S$2:$S$15000,"M.K. Chemical and Fertilizers") -> 196.912 | H48: =SUMIFS('WH+RT PREVIOUS'!$M$2:$M$15000,'WH+RT PREVIOUS'!$B$2:$B$15000,"Imp 10-26-26",'WH+RT PREVIOUS'!$S$2:$S$15000,"M.K. Chemical and Fertilizers") -> 25.4 | I48: =SUMIFS('WH+RT PREVIOUS'!$M$2:$M$15000,'WH+RT PREVIOUS'!$B$2:$B$15000,"MOP",'WH+RT PREVIOUS'!$S$2:$S$15000,"M.K. Chemical and Fertilizers") -> 48.434 | J48: =SUMIFS('WH+RT PREVIOUS'!$M$2:$M$15000,'WH+RT PREVIOUS'!$B$2:$B$15000,"Imp DAP",'WH+RT PREVIOUS'!$S$2:$S$15000,"M.K. Chemical and Fertilizers") -> 0 | K48: =F48+G48+H48+I48 -> 495.283 | L48: =SUMIFS('WH+RT CURRENT'!$M$2:$M$15000,'WH+RT CURRENT'!$B$2:$B$15000,"N.C.Urea(45kg)",'WH+RT CURRENT'!$S$2:$S$15000,"M.K. Chemical and Fertilizers") -> 210.807 | M48: =SUMIFS('WH+RT CURRENT'!$M$2:$M$15000,'WH+RT CURRENT'!$B$2:$B$15000,"15-15-15",'WH+RT CURRENT'!$S$2:$S$15000,"M.K. Chemical and Fertilizers") -> 167.312 | N48: =SUMIFS('WH+RT CURRENT'!$M$2:$M$15000,'WH+RT CURRENT'!$B$2:$B$15000,"Imp 10-26-26",'WH+RT CURRENT'!$S$2:$S$15000,"M.K. Chemical and Fertilizers") -> 23.45 | O48: =SUMIFS('WH+RT CURRENT'!$M$2:$M$15000,'WH+RT CURRENT'!$B$2:$B$15000,"MOP",'WH+RT CURRENT'!$S$2:$S$15000,"M.K. Chemical and Fertilizers") -> 44.634 | P48: =SUMIFS('WH+RT CURRENT'!$M$2:$M$15000,'WH+RT CURRENT'!$B$2:$B$15000,"Imp DAP",'WH+RT CURRENT'!$S$2:$S$15000,"M.K. Chemical and Fertilizers") -> 0 | Q48: =L48+M48+N48+O48 -> 446.203
E51: M/S. Shyma Krishi B
F52: Previous | L52: Current
F53: UREA | G53: S-15 | H53: 10-26-26 | I53: MOP | J53: DAP | K53: TOTAL | L53: UREA | M53: S-15 | N53: 10-26-26 | O53: MOP | P53: DAP | Q53: TOTAL
...

Sheet S24
E1: SOUTH 24 PARGANAS | R1: Total | S1: 9
E6: Hasya Badhan Makhal
F7: Previous | L7: Current
F8: UREA | G8: S-15 | H8: 10-26-26 | I8: MOP | J8: DAP | K8: TOTAL | L8: UREA | M8: S-15 | N8: 10-26-26 | O8: MOP | P8: DAP | Q8: TOTAL
E9: 181-365 | F9: =SUMIFS('WH+RT PREVIOUS'!$M$2:$M$15000,'WH+RT PREVIOUS'!$B$2:$B$15000,"N.C.Urea(45kg)",'WH+RT PREVIOUS'!$S$2:$S$15000,"Hasya Badhan Makhal",'WH+RT PREVIOUS'!$N$2:$N$15000,">179",'WH+RT PREVIOUS'!$N$2:$N$15000,"<366") -> 3.33 | G9: =SUMIFS('WH+RT PREVIOUS'!$M$2:$M$15000,'WH+RT PREVIOUS'!$B$2:$B$15000,"15-15-15",'WH+RT PREVIOUS'!$S$2:$S$15000,"Hasya Badhan Makhal",'WH+RT PREVIOUS'!$N$2:$N$15000,">179",'WH+RT PREVIOUS'!$N$2:$N$15000,"<366") -> 0 | H9: =SUMIFS('WH+RT PREVIOUS'!$M$2:$M$15000,'WH+RT PREVIOUS'!$B$2:$B$15000,"Imp 10-26-26",'WH+RT PREVIOUS'!$S$2:$S$15000,"Hasya Badhan Makhal",'WH+RT PREVIOUS'!$N$2:$N$15000,">179",'WH+RT PREVIOUS'!$N$2:$N$15000,"<366") -> 0 | I9: =SUMIFS('WH+RT PREVIOUS'!$M$2:$M$15000,'WH+RT PREVIOUS'!$B$2:$B$15000,"MOP",'WH+RT PREVIOUS'!$S$2:$S$15000,"Hasya Badhan Makhal",'WH+RT PREVIOUS'!$N$2:$N$15000,">179",'WH+RT PREVIOUS'!$N$2:$N$15000,"<366") -> 0.4 | J9: =SUMIFS('WH+RT PREVIOUS'!$M$2:$M$15000,'WH+RT PREVIOUS'!$B$2:$B$15000,"Imp DAP",'WH+RT PREVIOUS'!$S$2:$S$15000,"Hasya Badhan Makhal",'WH+RT PREVIOUS'!$N$2:$N$15000,">179",'WH+RT PREVIOUS'!$N$2:$N$15000,"<366") -> 0 | K9: =F9+G9+H9+I9+J9 -> 3.73 | L9: =SUMIFS('WH+RT CURRENT'!$M$2:$M$15000,'WH+RT CURRENT'!$B$2:$B$15000,"N.C.Urea(45kg)",'WH+RT CURRENT'!$S$2:$S$15000,"Hasya Badhan Makhal",'WH+RT CURRENT'!$N$2:$N$15000,">179",'WH+RT CURRENT'!$N$2:$N$15000,"<366") -> 3.33 | M9: =SUMIFS('WH+RT CURRENT'!$M$2:$M$15000,'WH+RT CURRENT'!$B$2:$B$15000,"15-15-15",'WH+RT CURRENT'!$S$2:$S$15000,"Hasya Badhan Makhal",'WH+RT CURRENT'!$N$2:$N$15000,">179",'WH+RT CURRENT'!$N$2:$N$15000,"<366") -> 0 | N9: =SUMIFS('WH+RT CURRENT'!$M$2:$M$15000,'WH+RT CURRENT'!$B$2:$B$15000,"Imp 10-26-26",'WH+RT CURRENT'!$S$2:$S$15000,"Hasya Badhan Makhal",'WH+RT CURRENT'!$N$2:$N$15000,">179",'WH+RT CURRENT'!$N$2:$N$15000,"<366") -> 0 | O9: =SUMIFS('WH+RT CURRENT'!$M$2:$M$15000,'WH+RT CURRENT'!$B$2:$B$15000,"MOP",'WH+RT CURRENT'!$S$2:$S$15000,"Hasya Badhan Makhal",'WH+RT CURRENT'!$N$2:$N$15000,">179",'WH+RT CURRENT'!$N$2:$N$15000,"<366") -> 0.4 | P9: =SUMIFS('WH+RT CURRENT'!$M$2:$M$15000,'WH+RT CURRENT'!$B$2:$B$15000,"Imp DAP",'WH+RT CURRENT'!$S$2:$S$15000,"Hasya Badhan Makhal",'WH+RT CURRENT'!$N$2:$N$15000,">179",'WH+RT CURRENT'!$N$2:$N$15000,"<366") -> 0 | Q9: =L9+M9+N9+O9+P9 -> 3.73
E10: 366+ | F10: =SUMIFS('WH+RT PREVIOUS'!$M$2:$M$15000,'WH+RT PREVIOUS'!$B$2:$B$15000,"N.C.Urea(45kg)",'WH+RT PREVIOUS'!$S$2:$S$15000,"Hasya Badhan Makhal",'WH+RT PREVIOUS'!$N$2:$N$15000,">365") -> 5.305 | G10: =SUMIFS('WH+RT PREVIOUS'!$M$2:$M$15000,'WH+RT PREVIOUS'!$B$2:$B$15000,"15-15-15",'WH+RT PREVIOUS'!$S$2:$S$15000,"Hasya Badhan Makhal",'WH+RT PREVIOUS'!$N$2:$N$15000,">365") -> 4.234 | H10: =SUMIFS('WH+RT PREVIOUS'!$M$2:$M$15000,'WH+RT PREVIOUS'!$B$2:$B$15000,"Imp 10-26-26",'WH+RT PREVIOUS'!$S$2:$S$15000,"Hasya Badhan Makhal",'WH+RT PREVIOUS'!$N$2:$N$15000,">365") -> 0 | I10: =SUMIFS('WH+RT PREVIOUS'!$M$2:$M$15000,'WH+RT PREVIOUS'!$B$2:$B$15000,"MOP",'WH+RT PREVIOUS'!$S$2:$S$15000,"Hasya Badhan Makhal",'WH+RT PREVIOUS'!$N$2:$N$15000,">365") -> 0 | J10: =SUMIFS('WH+RT PREVIOUS'!$M$2:$M$15000,'WH+RT PREVIOUS'!$B$2:$B$15000,"Imp DAP",'WH+RT PREVIOUS'!$S$2:$S$15000,"Hasya Badhan Makhal",'WH+RT PREVIOUS'!$N$2:$N$15000,">365") -> 0.15 | K10: =F10+G10+H10+I10+J10 -> 9.689 | L10: =SUMIFS('WH+RT CURRENT'!$M$2:$M$15000,'WH+RT CURRENT'!$B$2:$B$15000,"N.C.Urea(45kg)",'WH+RT CURRENT'!$S$2:$S$15000,"Hasya Badhan Makhal",'WH+RT CURRENT'!$N$2:$N$15000,">365") -> 5.305 | M10: =SUMIFS('WH+RT CURRENT'!$M$2:$M$15000,'WH+RT CURRENT'!$B$2:$B$15000,"15-15-15",'WH+RT CURRENT'!$S$2:$S$15000,"Hasya Badhan Makhal",'WH+RT CURRENT'!$N$2:$N$15000,">365") -> 4.234 | N10: =SUMIFS('WH+RT CURRENT'!$M$2:$M$15000,'WH+RT CURRENT'!$B$2:$B$15000,"Imp 10-26-26",'WH+RT CURRENT'!$S$2:$S$15000,"Hasya Badhan Makhal",'WH+RT CURRENT'!$N$2:$N$15000,">365") -> 0 | O10: =SUMIFS('WH+RT CURRENT'!$M$2:$M$15000,'WH+RT CURRENT'!$B$2:$B$15000,"MOP",'WH+RT CURRENT'!$S$2:$S$15000,"Hasya Badhan Makhal",'WH+RT CURRENT'!$N$2:$N$15000,">365") -> 0 | P10: =SUMIFS('WH+RT CURRENT'!$M$2:$M$15000,'WH+RT CURRENT'!$B$2:$B$15000,"Imp DAP",'WH+RT CURRENT'!$S$2:$S$15000,"Hasya Badhan Makhal",'WH+RT CURRENT'!$N$2:$N$15000,">365") -> 0.15 | Q10: =L10+M10+N10+O10+P10 -> 9.689
E11: GRAND TOTAL | F11: =F9+F10 -> 8.635 | G11: =G9+G10 -> 4.234 | H11: =H9+H10 -> 0 | I11: =I9+I10 -> 0.4 | J11: =J9+J10 -> 0.15 | K11: =F11+G11+H11+I11+J11 -> 13.419 | L11: =L9+L10 -> 8.635 | M11: =M9+M10 -> 4.234 | N11: =N9+N10 -> 0 | O11: =O9+O10 -> 0.4 | P11: =P9+P10 -> 0.15 | Q11: =L11+M11+N11+O11+P11 -> 13.419
E12: TOTAL STOCK | F12: =SUMIFS('WH+RT PREVIOUS'!$M$2:$M$15000,'WH+RT PREVIOUS'!$B$2:$B$15000,"N.C.Urea(45kg)",'WH+RT PREVIOUS'!$S$2:$S$15000,"Hasya Badhan Makhal") -> 62.998 | G12: =SUMIFS('WH+RT PREVIOUS'!$M$2:$M$15000,'WH+RT PREVIOUS'!$B$2:$B$15000,"15-15-15",'WH+RT PREVIOUS'!$S$2:$S$15000,"Hasya Badhan Makhal") -> 14.634 | H12: =SUMIFS('WH+RT PREVIOUS'!$M$2:$M$15000,'WH+RT PREVIOUS'!$B$2:$B$15000,"Imp 10-26-26",'WH+RT PREVIOUS'!$S$2:$S$15000,"Hasya Badhan Makhal") -> 5.2 | I12: =SUMIFS('WH+RT PREVIOUS'!$M$2:$M$15000,'WH+RT PREVIOUS'!$B$2:$B$15000,"MOP",'WH+RT PREVIOUS'!$S$2:$S$15000,"Hasya Badhan Makhal") -> 12.15 | J12: =SUMIFS('WH+RT PREVIOUS'!$M$2:$M$15000,'WH+RT PREVIOUS'!$B$2:$B$15000,"Imp DAP",'WH+RT PREVIOUS'!$S$2:$S$15000,"Hasya Badhan Makhal") -> 0.15 | K12: =F12+G12+H12+I12+J12 -> 95.132 | L12: =SUMIFS('WH+RT CURRENT'!$M$2:$M$15000,'WH+RT CURRENT'!$B$2:$B$15000,"N.C.Urea(45kg)",'WH+RT CURRENT'!$S$2:$S$15000,"Hasya Badhan Makhal") -> 62.998 | M12: =SUMIFS('WH+RT CURRENT'!$M$2:$M$15000,'WH+RT CURRENT'!$B$2:$B$15000,"15-15-15",'WH+RT CURRENT'!$S$2:$S$15000,"Hasya Badhan Makhal") -> 20.184 | N12: =SUMIFS('WH+RT CURRENT'!$M$2:$M$15000,'WH+RT CURRENT'!$B$2:$B$15000,"Imp 10-26-26",'WH+RT CURRENT'!$S$2:$S$15000,"Hasya Badhan Makhal") -> 4.7 | O12: =SUMIFS('WH+RT CURRENT'!$M$2:$M$15000,'WH+RT CURRENT'!$B$2:$B$15000,"MOP",'WH+RT CURRENT'!$S$2:$S$15000,"Hasya Badhan Makhal") -> 11.6 | P12: =SUMIFS('WH+RT CURRENT'!$M$2:$M$15000,'WH+RT CURRENT'!$B$2:$B$15000,"Imp DAP",'WH+RT CURRENT'!$S$2:$S$15000,"Hasya Badhan Makhal") -> 0.15 | Q12: =L12+M12+N12+O12+P12 -> 99.632
E15: Kirtibas Kapat (A.S.C.)
F16: Previous | L16: Current
F17: UREA | G17: S-15 | H17: 10-26-26 | I17: MOP | J17: DAP | K17: TOTAL | L17: UREA | M17: S-15 | N17: 10-26-26 | O17: MOP | P17: DAP | Q17: TOTAL
E18: 181-365 | F18: =SUMIFS('WH+RT PREVIOUS'!$M$2:$M$15000,'WH+RT PREVIOUS'!$B$2:$B$15000,"N.C.Urea(45kg)",'WH+RT PREVIOUS'!$S$2:$S$15000,"Kirtibas Kapat (A.S.C.)",'WH+RT PREVIOUS'!$N$2:$N$15000,">179",'WH+RT PREVIOUS'!$N$2:$N$15000,"<366") -> 8.636 | G18: =SUMIFS('WH+RT PREVIOUS'!$M$2:$M$15000,'WH+RT PREVIOUS'!$B$2:$B$15000,"15-15-15",'WH+RT PREVIOUS'!$S$2:$S$15000,"Kirtibas Kapat (A.S.C.)",'WH+RT PREVIOUS'!$N$2:$N$15000,">179",'WH+RT PREVIOUS'!$N$2:$N$15000,"<366") -> 0.52 | H18: =SUMIFS('WH+RT PREVIOUS'!$M$2:$M$15000,'WH+RT PREVIOUS'!$B$2:$B$15000,"Imp 10-26-26",'WH+RT PREVIOUS'!$S$2:$S$15000,"Kirtibas Kapat (A.S.C.)",'WH+RT PREVIOUS'!$N$2:$N$15000,">179",'WH+RT PREVIOUS'!$N$2:$N$15000,"<366") -> 0 | I18: =SUMIFS('WH+RT PREVIOUS'!$M$2:$M$15000,'WH+RT PREVIOUS'!$B$2:$B$15000,"MOP",'WH+RT PREVIOUS'!$S$2:$S$15000,"Kirtibas Kapat (A.S.C.)",'WH+RT PREVIOUS'!$N$2:$N$15000,">179",'WH+RT PREVIOUS'!$N$2:$N$15000,"<366") -> 0.25 | J18: =SUMIFS('WH+RT PREVIOUS'!$M$2:$M$15000,'WH+RT PREVIOUS'!$B$2:$B$15000,"Imp DAP",'WH+RT PREVIOUS'!$S$2:$S$15000,"Kirtibas Kapat (A.S.C.)",'WH+RT PREVIOUS'!$N$2:$N$15000,">179",'WH+RT PREVIOUS'!$N$2:$N$15000,"<366") -> 0 | K18: =F18+G18+H18+I18+J18 -> 9.406 | L18: =SUMIFS('WH+RT CURRENT'!$M$2:$M$15000,'WH+RT CURRENT'!$B$2:$B$15000,"N.C.Urea(45kg)",'WH+RT CURRENT'!$S$2:$S$15000,"Kirtibas Kapat (A.S.C.)",'WH+RT CURRENT'!$N$2:$N$15000,">179",'WH+RT CURRENT'!$N$2:$N$15000,"<366") -> 8.636 | M18: =SUMIFS('WH+RT CURRENT'!$M$2:$M$15000,'WH+RT CURRENT'!$B$2:$B$15000,"15-15-15",'WH+RT CURRENT'!$S$2:$S$15000,"Kirtibas Kapat (A.S.C.)",'WH+RT CURRENT'!$N$2:$N$15000,">179",'WH+RT CURRENT'!$N$2:$N$15000,"<366") -> 0.52 | N18: =SUMIFS('WH+RT CURRENT'!$M$2:$M$15000,'WH+RT CURRENT'!$B$2:$B$15000,"Imp 10-26-26",'WH+RT CURRENT'!$S$2:$S$15000,"Kirtibas Kapat (A.S.C.)",'WH+RT CURRENT'!$N$2:$N$15000,">179",'WH+RT CURRENT'!$N$2:$N$15000,"<366") -> 0 | O18: =SUMIFS('WH+RT CURRENT'!$M$2:$M$15000,'WH+RT CURRENT'!$B$2:$B$15000,"MOP",'WH+RT CURRENT'!$S$2:$S$15000,"Kirtibas Kapat (A.S.C.)",'WH+RT CURRENT'!$N$2:$N$15000,">179",'WH+RT CURRENT'!$N$2:$N$15000,"<366") -> 0.25 | P18: =SUMIFS('WH+RT CURRENT'!$M$2:$M$15000,'WH+RT CURRENT'!$B$2:$B$15000,"Imp DAP",'WH+RT CURRENT'!$S$2:$S$15000,"Kirtibas Kapat (A.S.C.)",'WH+RT CURRENT'!$N$2:$N$15000,">179",'WH+RT CURRENT'!$N$2:$N$15000,"<366") -> 0 | Q18: =L18+M18+N18+O18+P18 -> 9.406
E19: 366+ | F19: =SUMIFS('WH+RT PREVIOUS'!$M$2:$M$15000,'WH+RT PREVIOUS'!$B$2:$B$15000,"N.C.Urea(45kg)",'WH+RT PREVIOUS'!$S$2:$S$15000,"Kirtibas Kapat (A.S.C.)",'WH+RT PREVIOUS'!$N$2:$N$15000,">365") -> 8.92 | G19: =SUMIFS('WH+RT PREVIOUS'!$M$2:$M$15000,'WH+RT PREVIOUS'!$B$2:$B$15000,"15-15-15",'WH+RT PREVIOUS'!$S$2:$S$15000,"Kirtibas Kapat (A.S.C.)",'WH+RT PREVIOUS'!$N$2:$N$15000,">365") -> 4.464 | H19: =SUMIFS('WH+RT PREVIOUS'!$M$2:$M$15000,'WH+RT PREVIOUS'!$B$2:$B$15000,"Imp 10-26-26",'WH+RT PREVIOUS'!$S$2:$S$15000,"Kirtibas Kapat (A.S.C.)",'WH+RT PREVIOUS'!$N$2:$N$15000,">365") -> 0 | I19: =SUMIFS('WH+RT PREVIOUS'!$M$2:$M$15000,'WH+RT PREVIOUS'!$B$2:$B$15000,"MOP",'WH+RT PREVIOUS'!$S$2:$S$15000,"Kirtibas Kapat (A.S.C.)",'WH+RT PREVIOUS'!$N$2:$N$15000,">365") -> 1 | J19: =SUMIFS('WH+RT PREVIOUS'!$M$2:$M$15000,'WH+RT PREVIOUS'!$B$2:$B$15000,"Imp DAP",'WH+RT PREVIOUS'!$S$2:$S$15000,"Kirtibas Kapat (A.S.C.)",'WH+RT PREVIOUS'!$N$2:$N$15000,">365") -> 0 | K19: =F19+G19+H19+I19+J19 -> 14.384 | L19: =SUMIFS('WH+RT CURRENT'!$M$2:$M$15000,'WH+RT CURRENT'!$B$2:$B$15000,"N.C.Urea(45kg)",'WH+RT CURRENT'!$S$2:$S$15000,"Kirtibas Kapat (A.S.C.)",'WH+RT CURRENT'!$N$2:$N$15000,">365") -> 8.92 | M19: =SUMIFS('WH+RT CURRENT'!$M$2:$M$15000,'WH+RT CURRENT'!$B$2:$B$15000,"15-15-15",'WH+RT CURRENT'!$S$2:$S$15000,"Kirtibas Kapat (A.S.C.)",'WH+RT CURRENT'!$N$2:$N$15000,">365") -> 4.464 | N19: =SUMIFS('WH+RT CURRENT'!$M$2:$M$15000,'WH+RT CURRENT'!$B$2:$B$15000,"Imp 10-26-26",'WH+RT CURRENT'!$S$2:$S$15000,"Kirtibas Kapat (A.S.C.)",'WH+RT CURRENT'!$N$2:$N$15000,">365") -> 0 | O19: =SUMIFS('WH+RT CURRENT'!$M$2:$M$15000,'WH+RT CURRENT'!$B$2:$B$15000,"MOP",'WH+RT CURRENT'!$S$2:$S$15000,"Kirtibas Kapat (A.S.C.)",'WH+RT CURRENT'!$N$2:$N$15000,">365") -> 1 | P19: =SUMIFS('WH+RT CURRENT'!$M$2:$M$15000,'WH+RT CURRENT'!$B$2:$B$15000,"Imp DAP",'WH+RT CURRENT'!$S$2:$S$15000,"Kirtibas Kapat (A.S.C.)",'WH+RT CURRENT'!$N$2:$N$15000,">365") -> 0 | Q19: =L19+M19+N19+O19+P19 -> 14.384
E20: GRAND TOTAL | F20: =F18+F19 -> 17.556 | G20: =G18+G19 -> 4.984 | H20: =H18+H19 -> 0 | I20: =I18+I19 -> 1.25 | J20: =J18+J19 -> 0 | K20: =F20+G20+H20+I20+J20 -> 23.79 | L20: =L18+L19 -> 17.556 | M20: =M18+M19 -> 4.984 | N20: =N18+N19 -> 0 | O20: =O18+O19 -> 1.25 | P20: =P18+P19 -> 0 | Q20: =L20+M20+N20+O20+P20 -> 23.79
E21: TOTAL STOCK | F21: =SUMIFS('WH+RT PREVIOUS'!$M$2:$M$15000,'WH+RT PREVIOUS'!$B$2:$B$15000,"N.C.Urea(45kg)",'WH+RT PREVIOUS'!$S$2:$S$15000,"Kirtibas Kapat (A.S.C.)") -> 116.331 | G21: =SUMIFS('WH+RT PREVIOUS'!$M$2:$M$15000,'WH+RT PREVIOUS'!$B$2:$B$15000,"15-15-15",'WH+RT PREVIOUS'!$S$2:$S$15000,"Kirtibas Kapat (A.S.C.)") -> 40.529 | H21: =SUMIFS('WH+RT PREVIOUS'!$M$2:$M$15000,'WH+RT PREVIOUS'!$B$2:$B$15000,"Imp 10-26-26",'WH+RT PREVIOUS'!$S$2:$S$15000,"Kirtibas Kapat (A.S.C.)") -> 13.18 | I21: =SUMIFS('WH+RT PREVIOUS'!$M$2:$M$15000,'WH+RT PREVIOUS'!$B$2:$B$15000,"MOP",'WH+RT PREVIOUS'!$S$2:$S$15000,"Kirtibas Kapat (A.S.C.)") -> 15 | J21: =SUMIFS('WH+RT PREVIOUS'!$M$2:$M$15000,'WH+RT PREVIOUS'!$B$2:$B$15000,"Imp DAP",'WH+RT PREVIOUS'!$S$2:$S$15000,"Kirtibas Kapat (A.S.C.)") -> 0 | K21: =F21+G21+H21+I21+J21 -> 185.04 | L21: =SUMIFS('WH+RT CURRENT'!$M$2:$M$15000,'WH+RT CURRENT'!$B$2:$B$15000,"N.C.Urea(45kg)",'WH+RT CURRENT'!$S$2:$S$15000,"Kirtibas Kapat (A.S.C.)") -> 113.586 | M21: =SUMIFS('WH+RT CURRENT'!$M$2:$M$15000,'WH+RT CURRENT'!$B$2:$B$15000,"15-15-15",'WH+RT CURRENT'!$S$2:$S$15000,"Kirtibas Kapat (A.S.C.)") -> 48.629 | N21: =SUMIFS('WH+RT CURRENT'!$M$2:$M$15000,'WH+RT CURRENT'!$B$2:$B$15000,"Imp 10-26-26",'WH+RT CURRENT'!$S$2:$S$15000,"Kirtibas Kapat (A.S.C.)") -> 17.48 | O21: =SUMIFS('WH+RT CURRENT'!$M$2:$M$15000,'WH+RT CURRENT'!$B$2:$B$15000,"MOP",'WH+RT CURRENT'!$S$2:$S$15000,"Kirtibas Kapat (A.S.C.)") -> 12.9 | P21: =SUMIFS('WH+RT CURRENT'!$M$2:$M$15000,'WH+RT CURRENT'!$B$2:$B$15000,"Imp DAP",'WH+RT CURRENT'!$S$2:$S$15000,"Kirtibas Kapat (A.S.C.)") -> 0 | Q21: =L21+M21+N21+O21+P21 -> 192.595
E24: M/S TAPAN KUMAR KARMAKAR
F25: Previous | L25: Current
F26: UREA | G26: S-15 | H26: 10-26-26 | I26: MOP | J26: DAP | K26: TOTAL | L26: UREA | M26: S-15 | N26: 10-26-26 | O26: MOP | P26: DAP | Q26: TOTAL
E27: 181-365 | F27: =SUMIFS('WH+RT PREVIOUS'!$M$2:$M$15000,'WH+RT PREVIOUS'!$B$2:$B$15000,"N.C.Urea(45kg)",'WH+RT PREVIOUS'!$S$2:$S$15000,"M/S TAPAN KUMAR KARMAKAR",'WH+RT PREVIOUS'!$N$2:$N$15000,">179",'WH+RT PREVIOUS'!$N$2:$N$15000,"<366") -> 16.83 | G27: =SUMIFS('WH+RT PREVIOUS'!$M$2:$M$15000,'WH+RT PREVIOUS'!$B$2:$B$15000,"15-15-15",'WH+RT PREVIOUS'!$S$2:$S$15000,"M/S TAPAN KUMAR KARMAKAR",'WH+RT PREVIOUS'!$N$2:$N$15000,">179",'WH+RT PREVIOUS'!$N$2:$N$15000,"<366") -> 12.923 | H27: =SUMIFS('WH+RT PREVIOUS'!$M$2:$M$15000,'WH+RT PREVIOUS'!$B$2:$B$15000,"Imp 10-26-26",'WH+RT PREVIOUS'!$S$2:$S$15000,"M/S TAPAN KUMAR KARMAKAR",'WH+RT PREVIOUS'!$N$2:$N$15000,">179",'WH+RT PREVIOUS'!$N$2:$N$15000,"<366") -> 0 | I27: =SUMIFS('WH+RT PREVIOUS'!$M$2:$M$15000,'WH+RT PREVIOUS'!$B$2:$B$15000,"MOP",'WH+RT PREVIOUS'!$S$2:$S$15000,"M/S TAPAN KUMAR KARMAKAR",'WH+RT PREVIOUS'!$N$2:$N$15000,">179",'WH+RT PREVIOUS'!$N$2:$N$15000,"<366") -> 0 | J27: =SUMIFS('WH+RT PREVIOUS'!$M$2:$M$15000,'WH+RT PREVIOUS'!$B$2:$B$15000,"Imp DAP",'WH+RT PREVIOUS'!$S$2:$S$15000,"M/S TAPAN KUMAR KARMAKAR",'WH+RT PREVIOUS'!$N$2:$N$15000,">179",'WH+RT PREVIOUS'!$N$2:$N$15000,"<366") -> 0 | K27: =F27+G27+H27+I27+J27 -> 29.753 | L27: =SUMIFS('WH+RT CURRENT'!$M$2:$M$15000,'WH+RT CURRENT'!$B$2:$B$15000,"N.C.Urea(45kg)",'WH+RT CURRENT'!$S$2:$S$15000,"M/S TAPAN KUMAR KARMAKAR",'WH+RT CURRENT'!$N$2:$N$15000,">179",'WH+RT CURRENT'!$N$2:$N$15000,"<366") -> 16.695 | M27: =SUMIFS('WH+RT CURRENT'!$M$2:$M$15000,'WH+RT CURRENT'!$B$2:$B$15000,"15-15-15",'WH+RT CURRENT'!$S$2:$S$15000,"M/S TAPAN KUMAR KARMAKAR",'WH+RT CURRENT'!$N$2:$N$15000,">179",'WH+RT CURRENT'!$N$2:$N$15000,"<366") -> 12.423 | N27: =SUMIFS('WH+RT CURRENT'!$M$2:$M$15000,'WH+RT CURRENT'!$B$2:$B$15000,"Imp 10-26-26",'WH+RT CURRENT'!$S$2:$S$15000,"M/S TAPAN KUMAR KARMAKAR",'WH+RT CURRENT'!$N$2:$N$15000,">179",'WH+RT CURRENT'!$N$2:$N$15000,"<366") -> 0 | O27: =SUMIFS('WH+RT CURRENT'!$M$2:$M$15000,'WH+RT CURRENT'!$B$2:$B$15000,"MOP",'WH+RT CURRENT'!$S$2:$S$15000,"M/S TAPAN KUMAR KARMAKAR",'WH+RT CURRENT'!$N$2:$N$15000,">179",'WH+RT CURRENT'!$N$2:$N$15000,"<366") -> 0 | P27: =SUMIFS('WH+RT CURRENT'!$M$2:$M$15000,'WH+RT CURRENT'!$B$2:$B$15000,"Imp DAP",'WH+RT CURRENT'!$S$2:$S$15000,"M/S TAPAN KUMAR KARMAKAR",'WH+RT CURRENT'!$N$2:$N$15000,">179",'WH+RT CURRENT'!$N$2:$N$15000,"<366") -> 0 | Q27: =L27+M27+N27+O27+P27 -> 29.118
E28: 366+ | F28: =SUMIFS('WH+RT PREVIOUS'!$M$2:$M$15000,'WH+RT PREVIOUS'!$B$2:$B$15000,"N.C.Urea(45kg)",'WH+RT PREVIOUS'!$S$2:$S$15000,"M/S TAPAN KUMAR KARMAKAR",'WH+RT PREVIOUS'!$N$2:$N$15000,">365") -> 6.795 | G28: =SUMIFS('WH+RT PREVIOUS'!$M$2:$M$15000,'WH+RT PREVIOUS'!$B$2:$B$15000,"15-15-15",'WH+RT PREVIOUS'!$S$2:$S$15000,"M/S TAPAN KUMAR KARMAKAR",'WH+RT PREVIOUS'!$N$2:$N$15000,">365") -> 1 | H28: =SUMIFS('WH+RT PREVIOUS'!$M$2:$M$15000,'WH+RT PREVIOUS'!$B$2:$B$15000,"Imp 10-26-26",'WH+RT PREVIOUS'!$S$2:$S$15000,"M/S TAPAN KUMAR KARMAKAR",'WH+RT PREVIOUS'!$N$2:$N$15000,">365") -> 0 | I28: =SUMIFS('WH+RT PREVIOUS'!$M$2:$M$15000,'WH+RT PREVIOUS'!$B$2:$B$15000,"MOP",'WH+RT PREVIOUS'!$S$2:$S$15000,"M/S TAPAN KUMAR KARMAKAR",'WH+RT PREVIOUS'!$N$2:$N$15000,">365") -> 0 | J28: =SUMIFS('WH+RT PREVIOUS'!$M$2:$M$15000,'WH+RT PREVIOUS'!$B$2:$B$15000,"Imp DAP",'WH+RT PREVIOUS'!$S$2:$S$15000,"M/S TAPAN KUMAR KARMAKAR",'WH+RT PREVIOUS'!$N$2:$N$15000,">365") -> 0 | K28: =F28+G28+H28+I28+J28 -> 7.795 | L28: =SUMIFS('WH+RT CURRENT'!$M$2:$M$15000,'WH+RT CURRENT'!$B$2:$B$15000,"N.C.Urea(45kg)",'WH+RT CURRENT'!$S$2:$S$15000,"M/S TAPAN KUMAR KARMAKAR",'WH+RT CURRENT'!$N$2:$N$15000,">365") -> 6.795 | M28: =SUMIFS('WH+RT CURRENT'!$M$2:$M$15000,'WH+RT CURRENT'!$B$2:$B$15000,"15-15-15",'WH+RT CURRENT'!$S$2:$S$15000,"M/S TAPAN KUMAR KARMAKAR",'WH+RT CURRENT'!$N$2:$N$15000,">365") -> 1 | N28: =SUMIFS('WH+RT CURRENT'!$M$2:$M$15000,'WH+RT CURRENT'!$B$2:$B$15000,"Imp 10-26-26",'WH+RT CURRENT'!$S$2:$S$15000,"M/S TAPAN KUMAR KARMAKAR",'WH+RT CURRENT'!$N$2:$N$15000,">365") -> 0 | O28: =SUMIFS('WH+RT CURRENT'!$M$2:$M$15000,'WH+RT CURRENT'!$B$2:$B$15000,"MOP",'WH+RT CURRENT'!$S$2:$S$15000,"M/S TAPAN KUMAR KARMAKAR",'WH+RT CURRENT'!$N$2:$N$15000,">365") -> 0 | P28: =SUMIFS('WH+RT CURRENT'!$M$2:$M$15000,'WH+RT CURRENT'!$B$2:$B$15000,"Imp DAP",'WH+RT CURRENT'!$S$2:$S$15000,"M/S TAPAN KUMAR KARMAKAR",'WH+RT CURRENT'!$N$2:$N$15000,">365") -> 0 | Q28: =L28+M28+N28+O28+P28 -> 7.795
E29: GRAND TOTAL | F29: =F27+F28 -> 23.625 | G29: =G27+G28 -> 13.923 | H29: =H27+H28 -> 0 | I29: =I27+I28 -> 0 | J29: =J27+J28 -> 0 | K29: =F29+G29+H29+I29+J29 -> 37.548 | L29: =L27+L28 -> 23.49 | M29: =M27+M28 -> 13.423 | N29: =N27+N28 -> 0 | O29: =O27+O28 -> 0 | P29: =P27+P28 -> 0 | Q29: =L29+M29+N29+O29+P29 -> 36.913
E30: TOTAL STOCK | F30: =SUMIFS('WH+RT PREVIOUS'!$M$2:$M$15000,'WH+RT PREVIOUS'!$B$2:$B$15000,"N.C.Urea(45kg)",'WH+RT PREVIOUS'!$S$2:$S$15000,"M/S TAPAN KUMAR KARMAKAR") -> 50.985 | G30: =SUMIFS('WH+RT PREVIOUS'!$M$2:$M$15000,'WH+RT PREVIOUS'!$B$2:$B$15000,"15-15-15",'WH+RT PREVIOUS'!$S$2:$S$15000,"M/S TAPAN KUMAR KARMAKAR") -> 48.621 | H30: =SUMIFS('WH+RT PREVIOUS'!$M$2:$M$15000,'WH+RT PREVIOUS'!$B$2:$B$15000,"Imp 10-26-26",'WH+RT PREVIOUS'!$S$2:$S$15000,"M/S TAPAN KUMAR KARMAKAR") -> 0 | I30: =SUMIFS('WH+RT PREVIOUS'!$M$2:$M$15000,'WH+RT PREVIOUS'!$B$2:$B$15000,"MOP",'WH+RT PREVIOUS'!$S$2:$S$15000,"M/S TAPAN KUMAR KARMAKAR") -> 38.15 | J30: =SUMIFS('WH+RT PREVIOUS'!$M$2:$M$15000,'WH+RT PREVIOUS'!$B$2:$B$15000,"Imp DAP",'WH+RT PREVIOUS'!$S$2:$S$15000,"M/S TAPAN KUMAR KARMAKAR") -> 0 | K30: =F30+G30+H30+I30+J30 -> 137.756 | L30: =SUMIFS('WH+RT CURRENT'!$M$2:$M$15000,'WH+RT CURRENT'!$B$2:$B$15000,"N.C.Urea(45kg)",'WH+RT CURRENT'!$S$2:$S$15000,"M/S TAPAN KUMAR KARMAKAR") -> 49.23 | M30: =SUMIFS('WH+RT CURRENT'!$M$2:$M$15000,'WH+RT CURRENT'!$B$2:$B$15000,"15-15-15",'WH+RT CURRENT'!$S$2:$S$15000,"M/S TAPAN KUMAR KARMAKAR") -> 47.621 | N30: =SUMIFS('WH+RT CURRENT'!$M$2:$M$15000,'WH+RT CURRENT'!$B$2:$B$15000,"Imp 10-26-26",'WH+RT CURRENT'!$S$2:$S$15000,"M/S TAPAN KUMAR KARMAKAR") -> 0 | O30: =SUMIFS('WH+RT CURRENT'!$M$2:$M$15000,'WH+RT CURRENT'!$B$2:$B$15000,"MOP",'WH+RT CURRENT'!$S$2:$S$15000,"M/S TAPAN KUMAR KARMAKAR") -> 34.65 | P30: =SUMIFS('WH+RT CURRENT'!$M$2:$M$15000,'WH+RT CURRENT'!$B$2:$B$15000,"Imp DAP",'WH+RT CURRENT'!$S$2:$S$15000,"M/S TAPAN KUMAR KARMAKAR") -> 0 | Q30: =L30+M30+N30+O30+P30 -> 131.501
E33: M/s. Janardan Parui
F34: Previous | L34: Current
F35: UREA | G35: S-15 | H35: 10-26-26 | I35: MOP | J35: DAP | K35: TOTAL | L35: UREA | M35: S-15 | N35: 10-26-26 | O35: MOP | P35: DAP | Q35: TOTAL
E36: 181-365 | F36: =SUMIFS('WH+RT PREVIOUS'!$M$2:$M$15000,'WH+RT PREVIOUS'!$B$2:$B$15000,"N.C.Urea(45kg)",'WH+RT PREVIOUS'!$S$2:$S$15000,"M/s. Janardan Parui",'WH+RT PREVIOUS'!$N$2:$N$15000,">179",'WH+RT PREVIOUS'!$N$2:$N$15000,"<366") -> 0 | G36: =SUMIFS('WH+RT PREVIOUS'!$M$2:$M$15000,'WH+RT PREVIOUS'!$B$2:$B$15000,"15-15-15",'WH+RT PREVIOUS'!$S$2:$S$15000,"M/s. Janardan Parui",'WH+RT PREVIOUS'!$N$2:$N$15000,">179",'WH+RT PREVIOUS'!$N$2:$N$15000,"<366") -> 0.45 | H36: =SUMIFS('WH+RT PREVIOUS'!$M$2:$M$15000,'WH+RT PREVIOUS'!$B$2:$B$15000,"Imp 10-26-26",'WH+RT PREVIOUS'!$S$2:$S$15000,"M/s. Janardan Parui",'WH+RT PREVIOUS'!$N$2:$N$15000,">179",'WH+RT PREVIOUS'!$N$2:$N$15000,"<366") -> 0 | I36: =SUMIFS('WH+RT PREVIOUS'!$M$2:$M$15000,'WH+RT PREVIOUS'!$B$2:$B$15000,"MOP",'WH+RT PREVIOUS'!$S$2:$S$15000,"M/s. Janardan Parui",'WH+RT PREVIOUS'!$N$2:$N$15000,">179",'WH+RT PREVIOUS'!$N$2:$N$15000,"<366") -> 0 | J36: =SUMIFS('WH+RT PREVIOUS'!$M$2:$M$15000,'WH+RT PREVIOUS'!$B$2:$B$15000,"Imp DAP",'WH+RT PREVIOUS'!$S$2:$S$15000,"M/s. Janardan Parui",'WH+RT PREVIOUS'!$N$2:$N$15000,">179",'WH+RT PREVIOUS'!$N$2:$N$15000,"<366") -> 0 | K36: =F36+G36+H36+I36+J36 -> 0.45 | L36: =SUMIFS('WH+RT CURRENT'!$M$2:$M$15000,'WH+RT CURRENT'!$B$2:$B$15000,"N.C.Urea(45kg)",'WH+RT CURRENT'!$S$2:$S$15000,"M/s. Janardan Parui",'WH+RT CURRENT'!$N$2:$N$15000,">179",'WH+RT CURRENT'!$N$2:$N$15000,"<366") -> 0 | M36: =SUMIFS('WH+RT CURRENT'!$M$2:$M$15000,'WH+RT CURRENT'!$B$2:$B$15000,"15-15-15",'WH+RT CURRENT'!$S$2:$S$15000,"M/s. Janardan Parui",'WH+RT CURRENT'!$N$2:$N$15000,">179",'WH+RT CURRENT'!$N$2:$N$15000,"<366") -> 0.45 | N36: =SUMIFS('WH+RT CURRENT'!$M$2:$M$15000,'WH+RT CURRENT'!$B$2:$B$15000,"Imp 10-26-26",'WH+RT CURRENT'!$S$2:$S$15000,"M/s. Janardan Parui",'WH+RT CURRENT'!$N$2:$N$15000,">179",'WH+RT CURRENT'!$N$2:$N$15000,"<366") -> 0 | O36: =SUMIFS('WH+RT CURRENT'!$M$2:$M$15000,'WH+RT CURRENT'!$B$2:$B$15000,"MOP",'WH+RT CURRENT'!$S$2:$S$15000,"M/s. Janardan Parui",'WH+RT CURRENT'!$N$2:$N$15000,">179",'WH+RT CURRENT'!$N$2:$N$15000,"<366") -> 0 | P36: =SUMIFS('WH+RT CURRENT'!$M$2:$M$15000,'WH+RT CURRENT'!$B$2:$B$15000,"Imp DAP",'WH+RT CURRENT'!$S$2:$S$15000,"M/s. Janardan Parui",'WH+RT CURRENT'!$N$2:$N$15000,">179",'WH+RT CURRENT'!$N$2:$N$15000,"<366") -> 0 | Q36: =L36+M36+N36+O36+P36 -> 0.45
E37: 366+ | F37: =SUMIFS('WH+RT PREVIOUS'!$M$2:$M$15000,'WH+RT PREVIOUS'!$B$2:$B$15000,"N.C.Urea(45kg)",'WH+RT PREVIOUS'!$S$2:$S$15000,"M/s. Janardan Parui",'WH+RT PREVIOUS'!$N$2:$N$15000,">365") -> 5.093 | G37: =SUMIFS('WH+RT PREVIOUS'!$M$2:$M$15000,'WH+RT PREVIOUS'!$B$2:$B$15000,"15-15-15",'WH+RT PREVIOUS'!$S$2:$S$15000,"M/s. Janardan Parui",'WH+RT PREVIOUS'!$N$2:$N$15000,">365") -> 6.995 | H37: =SUMIFS('WH+RT PREVIOUS'!$M$2:$M$15000,'WH+RT PREVIOUS'!$B$2:$B$15000,"Imp 10-26-26",'WH+RT PREVIOUS'!$S$2:$S$15000,"M/s. Janardan Parui",'WH+RT PREVIOUS'!$N$2:$N$15000,">365") -> 0 | I37: =SUMIFS('WH+RT PREVIOUS'!$M$2:$M$15000,'WH+RT PREVIOUS'!$B$2:$B$15000,"MOP",'WH+RT PREVIOUS'!$S$2:$S$15000,"M/s. Janardan Parui",'WH+RT PREVIOUS'!$N$2:$N$15000,">365") -> 10.5 | J37: =SUMIFS('WH+RT PREVIOUS'!$M$2:$M$15000,'WH+RT PREVIOUS'!$B$2:$B$15000,"Imp DAP",'WH+RT PREVIOUS'!$S$2:$S$15000,"M/s. Janardan Parui",'WH+RT PREVIOUS'!$N$2:$N$15000,">365") -> 0 | K37: =F37+G37+H37+I37+J37 -> 22.588 | L37: =SUMIFS('WH+RT CURRENT'!$M$2:$M$15000,'WH+RT CURRENT'!$B$2:$B$15000,"N.C.Urea(45kg)",'WH+RT CURRENT'!$S$2:$S$15000,"M/s. Janardan Parui",'WH+RT CURRENT'!$N$2:$N$15000,">365") -> 5.093 | M37: =SUMIFS('WH+RT CURRENT'!$M$2:$M$15000,'WH+RT CURRENT'!$B$2:$B$15000,"15-15-15",'WH+RT CURRENT'!$S$2:$S$15000,"M/s. Janardan Parui",'WH+RT CURRENT'!$N$2:$N$15000,">365") -> 6.995 | N37: =SUMIFS('WH+RT CURRENT'!$M$2:$M$15000,'WH+RT CURRENT'!$B$2:$B$15000,"Imp 10-26-26",'WH+RT CURRENT'!$S$2:$S$15000,"M/s. Janardan Parui",'WH+RT CURRENT'!$N$2:$N$15000,">365") -> 0 | O37: =SUMIFS('WH+RT CURRENT'!$M$2:$M$15000,'WH+RT CURRENT'!$B$2:$B$15000,"MOP",'WH+RT CURRENT'!$S$2:$S$15000,"M/s. Janardan Parui",'WH+RT CURRENT'!$N$2:$N$15000,">365") -> 10.5 | P37: =SUMIFS('WH+RT CURRENT'!$M$2:$M$15000,'WH+RT CURRENT'!$B$2:$B$15000,"Imp DAP",'WH+RT CURRENT'!$S$2:$S$15000,"M/s. Janardan Parui",'WH+RT CURRENT'!$N$2:$N$15000,">365") -> 0 | Q37: =L37+M37+N37+O37+P37 -> 22.588
E38: GRAND TOTAL | F38: =F36+F37 -> 5.093 | G38: =G36+G37 -> 7.445 | H38: =H36+H37 -> 0 | I38: =I36+I37 -> 10.5 | J38: =J36+J37 -> 0 | K38: =F38+G38+H38+I38+J38 -> 23.038 | L38: =L36+L37 -> 5.093 | M38: =M36+M37 -> 7.445 | N38: =N36+N37 -> 0 | O38: =O36+O37 -> 10.5 | P38: =P36+P37 -> 0 | Q38: =L38+M38+N38+O38+P38 -> 23.038
E39: TOTAL STOCK | F39: =SUMIFS('WH+RT PREVIOUS'!$M$2:$M$15000,'WH+RT PREVIOUS'!$B$2:$B$15000,"N.C.Urea(45kg)",'WH+RT PREVIOUS'!$S$2:$S$15000,"M/s. Janardan Parui") -> 78.753 | G39: =SUMIFS('WH+RT PREVIOUS'!$M$2:$M$15000,'WH+RT PREVIOUS'!$B$2:$B$15000,"15-15-15",'WH+RT PREVIOUS'!$S$2:$S$15000,"M/s. Janardan Parui") -> 82.089 | H39: =SUMIFS('WH+RT PREVIOUS'!$M$2:$M$15000,'WH+RT PREVIOUS'!$B$2:$B$15000,"Imp 10-26-26",'WH+RT PREVIOUS'!$S$2:$S$15000,"M/s. Janardan Parui") -> 22.85 | I39: =SUMIFS('WH+RT PREVIOUS'!$M$2:$M$15000,'WH+RT PREVIOUS'!$B$2:$B$15000,"MOP",'WH+RT PREVIOUS'!$S$2:$S$15000,"M/s. Janardan Parui") -> 10.5 | J39: =SUMIFS('WH+RT PREVIOUS'!$M$2:$M$15000,'WH+RT PREVIOUS'!$B$2:$B$15000,"Imp DAP",'WH+RT PREVIOUS'!$S$2:$S$15000,"M/s. Janardan Parui") -> 0 | K39: =F39+G39+H39+I39+J39 -> 194.192 | L39: =SUMIFS('WH+RT CURRENT'!$M$2:$M$15000,'WH+RT CURRENT'!$B$2:$B$15000,"N.C.Urea(45kg)",'WH+RT CURRENT'!$S$2:$S$15000,"M/s. Janardan Parui") -> 75.603 | M39: =SUMIFS('WH+RT CURRENT'!$M$2:$M$15000,'WH+RT CURRENT'!$B$2:$B$15000,"15-15-15",'WH+RT CURRENT'!$S$2:$S$15000,"M/s. Janardan Parui") -> 81.302 | N39: =SUMIFS('WH+RT CURRENT'!$M$2:$M$15000,'WH+RT CURRENT'!$B$2:$B$15000,"Imp 10-26-26",'WH+RT CURRENT'!$S$2:$S$15000,"M/s. Janardan Parui") -> 22.25 | O39: =SUMIFS('WH+RT CURRENT'!$M$2:$M$15000,'WH+RT CURRENT'!$B$2:$B$15000,"MOP",'WH+RT CURRENT'!$S$2:$S$15000,"M/s. Janardan Parui") -> 10.5 | P39: =SUMIFS('WH+RT CURRENT'!$M$2:$M$15000,'WH+RT CURRENT'!$B$2:$B$15000,"Imp DAP",'WH+RT CURRENT'!$S$2:$S$15000,"M/s. Janardan Parui") -> 0 | Q39: =L39+M39+N39+O39+P39 -> 189.655
E42: Manoda Fertilisers
F43: Previous | L43: Current
F44: UREA | G44: S-15 | H44: 10-26-26 | I44: MOP | J44: DAP | K44: TOTAL | L44: UREA | M44: S-15 | N44: 10-26-26 | O44: MOP | P44: DAP | Q44: TOTAL
